Workbook

Sheet README
A1: Pauseiro & Vance Legal Group — Multi-Office Consolidation Model
B4: What this is
B5: A synthetic 3-office professional-services group (P&V Miami [Group HQ], P&V Chicago, P&V Dallas) with 18 months of GL, bank statement and budget data (Jan 2024 - Jun 2025), built as a portfolio piece for accounting / audit / controlling / FP&A roles.
B7: How the tabs fit together
B8: PQ_* tabs - raw data as Power Query would land it after combining the 3 offices' source exports (see power_query_steps.md for the M code). Nothing upstream of these tabs is manual.
B9: Close_Checklist - the month-end close task list for the open period (Jun 2025), so the workbook reads like an active close, not just a finished model.
B10: Trial_Balance - net movement by account, by entity and combined, for the open month. Every number is a live SUMIFS against PQ_GL_Data.
B11: Bank_Reconciliation - book-to-bank tie-out per entity: book balance + unrecorded bank items = adjusted book balance; bank balance + outstanding items = adjusted bank balance. The two adjusted figures agree, which is the point of a bank rec.
B12: Consolidation - Group P&L: each office's numbers, the combined total, and the intercompany elimination for the HQ shared-services billing, with a note on why operating income doesn't move even though revenue and expense both shrink.
B13: Budget_vs_Actual - variance by entity/account for the open month, flagged and ranked.
B14: Dashboard - KPI tiles and trend charts for the Group.
B16: What it's built to demonstrate
B17: Accounting / audit / controlling / FP&A: a full close cycle (accruals, reconciliations, variance review, period lock) across a multi-entity structure.
... B21: Data modeling - grain, keys, fact & dimension tables: schema.sql, with the grain and keys of every fact table documented inline.

Sheet Dashboard
A1: Pauseiro & Vance Legal Group — Executive Dashboard — 2025-06
A3: Group Revenue (Net) | C3: Group Operating Income | E3: Group Operating Margin | G3: Open Bank Reconciling Items | I3: Largest Budget Overspend
A4: =Consolidation!E25 -> 241003.08 | C4: =Consolidation!E28 -> 60162.38 | E4: =Consolidation!E28/Consolidation!E25 -> 0.24963324 | G4: =COUNTIFS(PQ_Bank_Data!$H:$H,"2025-06",PQ_Bank_Data!$F:$F,"Unmatched - Book Adjustment Needed")+SUMPRODUCT(--(Bank_Reconciliation!$B$9:$D$9<>0)) -> 9 | I4: =INDEX(Budget_vs_Actual!$E:$E,MATCH(1,Budget_vs_Actual!$G:$G,0)) -> 1648.7

Sheet Close_Checklist
A1: Month-End Close Checklist — 2025-06 (Group)
A3: # | B3: Close Task | C3: Entity Scope | D3: Owner | E3: Due (business day) | F3: Status
A4: 1 | B4: Post final billing & cash receipts | C4: All entities | D4: Office Bookkeeper | E4: BD+2 | F4: Complete
A5: 2 | B5: Reverse prior-month payroll accrual | C5: All entities | D5: Controller | E5: BD+1 | F5: Complete
A6: 3 | B6: Run payroll & book current accrual | C6: All entities | D6: Controller | E6: BD+3 | F6: Complete
A7: 4 | B7: Amortize prepaid insurance | C7: All entities | D7: Controller | E7: BD+3 | F7: Complete
A8: 5 | B8: Book monthly depreciation | C8: All entities | D8: Controller | E8: BD+3 | F8: Complete
A9: 6 | B9: Bill intercompany shared services (HQ to branches) | C9: MIA -> CHI, DAL | D9: Controller | E9: BD+4 | F9: Complete
A10: 7 | B10: Settle prior-month intercompany balances | C10: CHI, DAL -> MIA | D10: Controller | E10: BD+5 | F10: Complete
A11: 8 | B11: Complete bank reconciliation, all accounts | C11: All entities | D11: Controller | E11: BD+5 | F11: In Progress
A12: 9 | B12: Book bank-identified items not yet in GL (fees, interest) | C12: All entities | D12: Controller | E12: BD+5 | F12: Not Started
A13: 10 | B13: Reconcile intercompany AR/AP between entities | C13: MIA, CHI, DAL | D13: Group Controller | E13: BD+6 | F13: Not Started
A14: 11 | B14: Prepare consolidation elimination entries | C14: Group | D14: Group Controller | E14: BD+6 | F14: Not Started
A15: 12 | B15: Review budget-vs-actual variances >10% | C15: All entities | D15: FP&A | E15: BD+7 | F15: Blocked
... A18: 15 | B18: Distribute close package | C18: Group | D18: Group Controller | E18: BD+9 | F18: Not Started
B20: Note: "Blocked" - budget-vs-actual review is waiting on the shared-services allocation reconciliation (task 10) to close first.

Sheet Trial_Balance
A1: Trial Balance — Net Movement by Account — 2025-06
A3: Account Code | B3: Account Name | C3: Account Type | D3: MIA | E3: CHI | F3: DAL | G3: Combined
A4: 1000 | B4: Cash - Operating | C4: Asset | D4: =SUMIFS(PQ_GL_Data!$I:$I,PQ_GL_Data!$C:$C,"MIA",PQ_GL_Data!$E:$E,"1000",PQ_GL_Data!$N:$N,"2025-06")-SUMIFS(PQ_GL_Data!$J:$J,PQ_GL_Data!$C:$C,"MIA",PQ_GL_Data!$E:$E,"1000",PQ_GL_Data!$N:$N,"2025-06") -> 33024.53 | E4: =SUMIFS(PQ_GL_Data!$I:$I,PQ_GL_Data!$C:$C,"CHI",PQ_GL_Data!$E:$E,"1000",PQ_GL_Data!$N:$N,"2025-06")-SUMIFS(PQ_GL_Data!$J:$J,PQ_GL_Data!$C:$C,"CHI",PQ_GL_Data!$E:$E,"1000",PQ_GL_Data!$N:$N,"2025-06") -> 10400.85 | F4: =SUMIFS(PQ_GL_Data!$I:$I,PQ_GL_Data!$C:$C,"DAL",PQ_GL_Data!$E:$E,"1000",PQ_GL_Data!$N:$N,"2025-06")-SUMIFS(PQ_GL_Data!$J:$J,PQ_GL_Data!$C:$C,"DAL",PQ_GL_Data!$E:$E,"1000",PQ_GL_Data!$N:$N,"2025-06") -> 7680.73 | G4: =SUM(D4:F4) -> 51106.11
A5: 1100 | B5: Accounts Receivable | C5: Asset | D5: =SUMIFS(PQ_GL_Data!$I:$I,PQ_GL_Data!$C:$C,"MIA",PQ_GL_Data!$E:$E,"1100",PQ_GL_Data!$N:$N,"2025-06")-SUMIFS(PQ_GL_Data!$J:$J,PQ_GL_Data!$C:$C,"MIA",PQ_GL_Data!$E:$E,"1100",PQ_GL_Data!$N:$N,"2025-06") -> 6868.81 | E5: =SUMIFS(PQ_GL_Data!$I:$I,PQ_GL_Data!$C:$C,"CHI",PQ_GL_Data!$E:$E,"1100",PQ_GL_Data!$N:$N,"2025-06")-SUMIFS(PQ_GL_Data!$J:$J,PQ_GL_Data!$C:$C,"CHI",PQ_GL_Data!$E:$E,"1100",PQ_GL_Data!$N:$N,"2025-06") -> 5680.75 | F5: =SUMIFS(PQ_GL_Data!$I:$I,PQ_GL_Data!$C:$C,"DAL",PQ_GL_Data!$E:$E,"1100",PQ_GL_Data!$N:$N,"2025-06")-SUMIFS(PQ_GL_Data!$J:$J,PQ_GL_Data!$C:$C,"DAL",PQ_GL_Data!$E:$E,"1100",PQ_GL_Data!$N:$N,"2025-06") -> 2407.11 | G5: =SUM(D5:F5) -> 14956.67
A6: 1200 | B6: Prepaid Expenses | C6: Asset | D6: =SUMIFS(PQ_GL_Data!$I:$I,PQ_GL_Data!$C:$C,"MIA",PQ_GL_Data!$E:$E,"1200",PQ_GL_Data!$N:$N,"2025-06")-SUMIFS(PQ_GL_Data!$J:$J,PQ_GL_Data!$C:$C,"MIA",PQ_GL_Data!$E:$E,"1200",PQ_GL_Data!$N:$N,"2025-06") -> -1450 | E6: =SUMIFS(PQ_GL_Data!$I:$I,PQ_GL_Data!$C:$C,"CHI",PQ_GL_Data!$E:$E,"1200",PQ_GL_Data!$N:$N,"2025-06")-SUMIFS(PQ_GL_Data!$J:$J,PQ_GL_Data!$C:$C,"CHI",PQ_GL_Data!$E:$E,"1200",PQ_GL_Data!$N:$N,"2025-06") -> -899 | F6: =SUMIFS(PQ_GL_Data!$I:$I,PQ_GL_Data!$C:$C,"DAL",PQ_GL_Data!$E:$E,"1200",PQ_GL_Data!$N:$N,"2025-06")-SUMIFS(PQ_GL_Data!$J:$J,PQ_GL_Data!$C:$C,"DAL",PQ_GL_Data!$E:$E,"1200",PQ_GL_Data!$N:$N,"2025-06") -> -797.5 | G6: =SUM(D6:F6) -> -3146.5
A7: 1300 | B7: Intercompany Receivable | C7: Asset | D7: =SUMIFS(PQ_GL_Data!$I:$I,PQ_GL_Data!$C:$C,"MIA",PQ_GL_Data!$E:$E,"1300",PQ_GL_Data!$N:$N,"2025-06")-SUMIFS(PQ_GL_Data!$J:$J,PQ_GL_Data!$C:$C,"MIA",PQ_GL_Data!$E:$E,"1300",PQ_GL_Data!$N:$N,"2025-06") -> 60.84 | E7: =SUMIFS(PQ_GL_Data!$I:$I,PQ_GL_Data!$C:$C,"CHI",PQ_GL_Data!$E:$E,"1300",PQ_GL_Data!$N:$N,"2025-06")-SUMIFS(PQ_GL_Data!$J:$J,PQ_GL_Data!$C:$C,"CHI",PQ_GL_Data!$E:$E,"1300",PQ_GL_Data!$N:$N,"2025-06") -> 0 | F7: =SUMIFS(PQ_GL_Data!$I:$I,PQ_GL_Data!$C:$C,"DAL",PQ_GL_Data!$E:$E,"1300",PQ_GL_Data!$N:$N,"2025-06")-SUMIFS(PQ_GL_Data!$J:$J,PQ_GL_Data!$C:$C,"DAL",PQ_GL_Data!$E:$E,"1300",PQ_GL_Data!$N:$N,"2025-06") -> 0 | G7: =SUM(D7:F7) -> 60.84
A8: 1500 | B8: Fixed Assets, Net | C8: Asset | D8: =SUMIFS(PQ_GL_Data!$I:$I,PQ_GL_Data!$C:$C,"MIA",PQ_GL_Data!$E:$E,"1500",PQ_GL_Data!$N:$N,"2025-06")-SUMIFS(PQ_GL_Data!$J:$J,PQ_GL_Data!$C:$C,"MIA",PQ_GL_Data!$E:$E,"1500",PQ_GL_Data!$N:$N,"2025-06") -> -1100 | E8: =SUMIFS(PQ_GL_Data!$I:$I,PQ_GL_Data!$C:$C,"CHI",PQ_GL_Data!$E:$E,"1500",PQ_GL_Data!$N:$N,"2025-06")-SUMIFS(PQ_GL_Data!$J:$J,PQ_GL_Data!$C:$C,"CHI",PQ_GL_Data!$E:$E,"1500",PQ_GL_Data!$N:$N,"2025-06") -> -682 | F8: =SUMIFS(PQ_GL_Data!$I:$I,PQ_GL_Data!$C:$C,"DAL",PQ_GL_Data!$E:$E,"1500",PQ_GL_Data!$N:$N,"2025-06")-SUMIFS(PQ_GL_Data!$J:$J,PQ_GL_Data!$C:$C,"DAL",PQ_GL_Data!$E:$E,"1500",PQ_GL_Data!$N:$N,"2025-06") -> -605 | G8: =SUM(D8:F8) -> -2387
A9: 2000 | B9: Accounts Payable | C9: Liability | D9: =SUMIFS(PQ_GL_Data!$I:$I,PQ_GL_Data!$C:$C,"MIA",PQ_GL_Data!$E:$E,"2000",PQ_GL_Data!$N:$N,"2025-06")-SUMIFS(PQ_GL_Data!$J:$J,PQ_GL_Data!$C:$C,"MIA",PQ_GL_Data!$E:$E,"2000",PQ_GL_Data!$N:$N,"2025-06") -> -73.69 | E9: =SUMIFS(PQ_GL_Data!$I:$I,PQ_GL_Data!$C:$C,"CHI",PQ_GL_Data!$E:$E,"2000",PQ_GL_Data!$N:$N,"2025-06")-SUMIFS(PQ_GL_Data!$J:$J,PQ_GL_Data!$C:$C,"CHI",PQ_GL_Data!$E:$E,"2000",PQ_GL_Data!$N:$N,"2025-06") -> -107.98 | F9: =SUMIFS(PQ_GL_Data!$I:$I,PQ_GL_Data!$C:$C,"DAL",PQ_GL_Data!$E:$E,"2000",PQ_GL_Data!$N:$N,"2025-06")-SUMIFS(PQ_GL_Data!$J:$J,PQ_GL_Data!$C:$C,"DAL",PQ_GL_Data!$E:$E,"2000",PQ_GL_Data!$N:$N,"2025-06") -> -63.51 | G9: =SUM(D9:F9) -> -245.18
A10: 2100 | B10: Accrued Payroll | C10: Liability | D10: =SUMIFS(PQ_GL_Data!$I:$I,PQ_GL_Data!$C:$C,"MIA",PQ_GL_Data!$E:$E,"2100",PQ_GL_Data!$N:$N,"2025-06")-SUMIFS(PQ_GL_Data!$J:$J,PQ_GL_Data!$C:$C,"MIA",PQ_GL_Data!$E:$E,"2100",PQ_GL_Data!$N:$N,"2025-06") -> -56.09 | E10: =SUMIFS(PQ_GL_Data!$I:$I,PQ_GL_Data!$C:$C,"CHI",PQ_GL_Data!$E:$E,"2100",PQ_GL_Data!$N:$N,"2025-06")-SUMIFS(PQ_GL_Data!$J:$J,PQ_GL_Data!$C:$C,"CHI",PQ_GL_Data!$E:$E,"2100",PQ_GL_Data!$N:$N,"2025-06") -> -34.78 | F10: =SUMIFS(PQ_GL_Data!$I:$I,PQ_GL_Data!$C:$C,"DAL",PQ_GL_Data!$E:$E,"2100",PQ_GL_Data!$N:$N,"2025-06")-SUMIFS(PQ_GL_Data!$J:$J,PQ_GL_Data!$C:$C,"DAL",PQ_GL_Data!$E:$E,"2100",PQ_GL_Data!$N:$N,"2025-06") -> -30.85 | G10: =SUM(D10:F10) -> -121.72
A11: 2200 | B11: Intercompany Payable | C11: Liability | D11: =SUMIFS(PQ_GL_Data!$I:$I,PQ_GL_Data!$C:$C,"MIA",PQ_GL_Data!$E:$E,"2200",PQ_GL_Data!$N:$N,"2025-06")-SUMIFS(PQ_GL_Data!$J:$J,PQ_GL_Data!$C:$C,"MIA",PQ_GL_Data!$E:$E,"2200",PQ_GL_Data!$N:$N,"2025-06") -> 0 | E11: =SUMIFS(PQ_GL_Data!$I:$I,PQ_GL_Data!$C:$C,"CHI",PQ_GL_Data!$E:$E,"2200",PQ_GL_Data!$N:$N,"2025-06")-SUMIFS(PQ_GL_Data!$J:$J,PQ_GL_Data!$C:$C,"CHI",PQ_GL_Data!$E:$E,"2200",PQ_GL_Data!$N:$N,"2025-06") -> -32.24 | F11: =SUMIFS(PQ_GL_Data!$I:$I,PQ_GL_Data!$C:$C,"DAL",PQ_GL_Data!$E:$E,"2200",PQ_GL_Data!$N:$N,"2025-06")-SUMIFS(PQ_GL_Data!$J:$J,PQ_GL_Data!$C:$C,"DAL",PQ_GL_Data!$E:$E,"2200",PQ_GL_Data!$N:$N,"2025-06") -> -28.6 | G11: =SUM(D11:F11) -> -60.84
A12: 3000 | B12: Owner's Equity / Retained Earnings | C12: Equity | D12: =SUMIFS(PQ_GL_Data!$I:$I,PQ_GL_Data!$C:$C,"MIA",PQ_GL_Data!$E:$E,"3000",PQ_GL_Data!$N:$N,"2025-06")-SUMIFS(PQ_GL_Data!$J:$J,PQ_GL_Data!$C:$C,"MIA",PQ_GL_Data!$E:$E,"3000",PQ_GL_Data!$N:$N,"2025-06") -> 0 | E12: =SUMIFS(PQ_GL_Data!$I:$I,PQ_GL_Data!$C:$C,"CHI",PQ_GL_Data!$E:$E,"3000",PQ_GL_Data!$N:$N,"2025-06")-SUMIFS(PQ_GL_Data!$J:$J,PQ_GL_Data!$C:$C,"CHI",PQ_GL_Data!$E:$E,"3000",PQ_GL_Data!$N:$N,"2025-06") -> 0 | F12: =SUMIFS(PQ_GL_Data!$I:$I,PQ_GL_Data!$C:$C,"DAL",PQ_GL_Data!$E:$E,"3000",PQ_GL_Data!$N:$N,"2025-06")-SUMIFS(PQ_GL_Data!$J:$J,PQ_GL_Data!$C:$C,"DAL",PQ_GL_Data!$E:$E,"3000",PQ_GL_Data!$N:$N,"2025-06") -> 0 | G12: =SUM(D12:F12) -> 0
A13: 4000 | B13: Legal Fee Revenue | C13: Revenue | D13: =SUMIFS(PQ_GL_Data!$I:$I,PQ_GL_Data!$C:$C,"MIA",PQ_GL_Data!$E:$E,"4000",PQ_GL_Data!$N:$N,"2025-06")-SUMIFS(PQ_GL_Data!$J:$J,PQ_GL_Data!$C:$C,"MIA",PQ_GL_Data!$E:$E,"4000",PQ_GL_Data!$N:$N,"2025-06") -> 0 | E13: =SUMIFS(PQ_GL_Data!$I:$I,PQ_GL_Data!$C:$C,"CHI",PQ_GL_Data!$E:$E,"4000",PQ_GL_Data!$N:$N,"2025-06")-SUMIFS(PQ_GL_Data!$J:$J,PQ_GL_Data!$C:$C,"CHI",PQ_GL_Data!$E:$E,"4000",PQ_GL_Data!$N:$N,"2025-06") -> 0 | F13: =SUMIFS(PQ_GL_Data!$I:$I,PQ_GL_Data!$C:$C,"DAL",PQ_GL_Data!$E:$E,"4000",PQ_GL_Data!$N:$N,"2025-06")-SUMIFS(PQ_GL_Data!$J:$J,PQ_GL_Data!$C:$C,"DAL",PQ_GL_Data!$E:$E,"4000",PQ_GL_Data!$N:$N,"2025-06") -> 0 | G13: =SUM(D13:F13) -> 0
A14: 4010 | B14: Litigation Fees | C14: Revenue | D14: =SUMIFS(PQ_GL_Data!$I:$I,PQ_GL_Data!$C:$C,"MIA",PQ_GL_Data!$E:$E,"4010",PQ_GL_Data!$N:$N,"2025-06")-SUMIFS(PQ_GL_Data!$J:$J,PQ_GL_Data!$C:$C,"MIA",PQ_GL_Data!$E:$E,"4010",PQ_GL_Data!$N:$N,"2025-06") -> -47822.5 | E14: =SUMIFS(PQ_GL_Data!$I:$I,PQ_GL_Data!$C:$C,"CHI",PQ_GL_Data!$E:$E,"4010",PQ_GL_Data!$N:$N,"2025-06")-SUMIFS(PQ_GL_Data!$J:$J,PQ_GL_Data!$C:$C,"CHI",PQ_GL_Data!$E:$E,"4010",PQ_GL_Data!$N:$N,"2025-06") -> -29360.01 | F14: =SUMIFS(PQ_GL_Data!$I:$I,PQ_GL_Data!$C:$C,"DAL",PQ_GL_Data!$E:$E,"4010",PQ_GL_Data!$N:$N,"2025-06")-SUMIFS(PQ_GL_Data!$J:$J,PQ_GL_Data!$C:$C,"DAL",PQ_GL_Data!$E:$E,"4010",PQ_GL_Data!$N:$N,"2025-06") -> -24038.78 | G14: =SUM(D14:F14) -> -101221.29
A15: 4020 | B15: Corporate & Transactional Fees | C15: Revenue | D15: =SUMIFS(PQ_GL_Data!$I:$I,PQ_GL_Data!$C:$C,"MIA",PQ_GL_Data!$E:$E,"4020",PQ_GL_Data!$N:$N,"2025-06")-SUMIFS(PQ_GL_Data!$J:$J,PQ_GL_Data!$C:$C,"MIA",PQ_GL_Data!$E:$E,"4020",PQ_GL_Data!$N:$N,"2025-06") -> -37574.82 | E15: =SUMIFS(PQ_GL_Data!$I:$I,PQ_GL_Data!$C:$C,"CHI",PQ_GL_Data!$E:$E,"4020",PQ_GL_Data!$N:$N,"2025-06")-SUMIFS(PQ_GL_Data!$J:$J,PQ_GL_Data!$C:$C,"CHI",PQ_GL_Data!$E:$E,"4020",PQ_GL_Data!$N:$N,"2025-06") -> -23068.58 | F15: =SUMIFS(PQ_GL_Data!$I:$I,PQ_GL_Data!$C:$C,"DAL",PQ_GL_Data!$E:$E,"4020",PQ_GL_Data!$N:$N,"2025-06")-SUMIFS(PQ_GL_Data!$J:$J,PQ_GL_Data!$C:$C,"DAL",PQ_GL_Data!$E:$E,"4020",PQ_GL_Data!$N:$N,"2025-06") -> -18887.62 | G15: =SUM(D15:F15) -> -79531.02
A16: 4030 | B16: Family Law Fees | C16: Revenue | D16: =SUMIFS(PQ_GL_Data!$I:$I,PQ_GL_Data!$C:$C,"MIA",PQ_GL_Data!$E:$E,"4030",PQ_GL_Data!$N:$N,"2025-06")-SUMIFS(PQ_GL_Data!$J:$J,PQ_GL_Data!$C:$C,"MIA",PQ_GL_Data!$E:$E,"4030",PQ_GL_Data!$N:$N,"2025-06") -> -28465.78 | E16: =SUMIFS(PQ_GL_Data!$I:$I,PQ_GL_Data!$C:$C,"CHI",PQ_GL_Data!$E:$E,"4030",PQ_GL_Data!$N:$N,"2025-06")-SUMIFS(PQ_GL_Data!$J:$J,PQ_GL_Data!$C:$C,"CHI",PQ_GL_Data!$E:$E,"4030",PQ_GL_Data!$N:$N,"2025-06") -> -17476.19 | F16: =SUMIFS(PQ_GL_Data!$I:$I,PQ_GL_Data!$C:$C,"DAL",PQ_GL_Data!$E:$E,"4030",PQ_GL_Data!$N:$N,"2025-06")-SUMIFS(PQ_GL_Data!$J:$J,PQ_GL_Data!$C:$C,"DAL",PQ_GL_Data!$E:$E,"4030",PQ_GL_Data!$N:$N,"2025-06") -> -14308.8 | G16: =SUM(D16:F16) -> -60250.77
A17: 4090 | B17: Intercompany Shared Services Revenue | C17: Revenue | D17: =SUMIFS(PQ_GL_Data!$I:$I,PQ_GL_Data!$C:$C,"MIA",PQ_GL_Data!$E:$E,"4090",PQ_GL_Data!$N:$N,"2025-06")-SUMIFS(PQ_GL_Data!$J:$J,PQ_GL_Data!$C:$C,"MIA",PQ_GL_Data!$E:$E,"4090",PQ_GL_Data!$N:$N,"2025-06") -> -7118.28 | E17: =SUMIFS(PQ_GL_Data!$I:$I,PQ_GL_Data!$C:$C,"CHI",PQ_GL_Data!$E:$E,"4090",PQ_GL_Data!$N:$N,"2025-06")-SUMIFS(PQ_GL_Data!$J:$J,PQ_GL_Data!$C:$C,"CHI",PQ_GL_Data!$E:$E,"4090",PQ_GL_Data!$N:$N,"2025-06") -> 0 | F17: =SUMIFS(PQ_GL_Data!$I:$I,PQ_GL_Data!$C:$C,"DAL",PQ_GL_Data!$E:$E,"4090",PQ_GL_Data!$N:$N,"2025-06")-SUMIFS(PQ_GL_Data!$J:$J,PQ_GL_Data!$C:$C,"DAL",PQ_GL_Data!$E:$E,"4090",PQ_GL_Data!$N:$N,"2025-06") -> 0 | G17: =SUM(D17:F17) -> -7118.28
A18: 5000 | B18: Direct Case Costs | C18: COGS | D18: =SUMIFS(PQ_GL_Data!$I:$I,PQ_GL_Data!$C:$C,"MIA",PQ_GL_Data!$E:$E,"5000",PQ_GL_Data!$N:$N,"2025-06")-SUMIFS(PQ_GL_Data!$J:$J,PQ_GL_Data!$C:$C,"MIA",PQ_GL_Data!$E:$E,"5000",PQ_GL_Data!$N:$N,"2025-06") -> 0 | E18: =SUMIFS(PQ_GL_Data!$I:$I,PQ_GL_Data!$C:$C,"CHI",PQ_GL_Data!$E:$E,"5000",PQ_GL_Data!$N:$N,"2025-06")-SUMIFS(PQ_GL_Data!$J:$J,PQ_GL_Data!$C:$C,"CHI",PQ_GL_Data!$E:$E,"5000",PQ_GL_Data!$N:$N,"2025-06") -> 0 | F18: =SUMIFS(PQ_GL_Data!$I:$I,PQ_GL_Data!$C:$C,"DAL",PQ_GL_Data!$E:$E,"5000",PQ_GL_Data!$N:$N,"2025-06")-SUMIFS(PQ_GL_Data!$J:$J,PQ_GL_Data!$C:$C,"DAL",PQ_GL_Data!$E:$E,"5000",PQ_GL_Data!$N:$N,"2025-06") -> 0 | G18: =SUM(D18:F18) -> 0
A19: 5010 | B19: Court Filing Fees | C19: COGS | D19: =SUMIFS(PQ_GL_Data!$I:$I,PQ_GL_Data!$C:$C,"MIA",PQ_GL_Data!$E:$E,"5010",PQ_GL_Data!$N:$N,"2025-06")-SUMIFS(PQ_GL_Data!$J:$J,PQ_GL_Data!$C:$C,"MIA",PQ_GL_Data!$E:$E,"5010",PQ_GL_Data!$N:$N,"2025-06") -> 6466.68 | E19: =SUMIFS(PQ_GL_Data!$I:$I,PQ_GL_Data!$C:$C,"CHI",PQ_GL_Data!$E:$E,"5010",PQ_GL_Data!$N:$N,"2025-06")-SUMIFS(PQ_GL_Data!$J:$J,PQ_GL_Data!$C:$C,"CHI",PQ_GL_Data!$E:$E,"5010",PQ_GL_Data!$N:$N,"2025-06") -> 3970.14 | F19: =SUMIFS(PQ_GL_Data!$I:$I,PQ_GL_Data!$C:$C,"DAL",PQ_GL_Data!$E:$E,"5010",PQ_GL_Data!$N:$N,"2025-06")-SUMIFS(PQ_GL_Data!$J:$J,PQ_GL_Data!$C:$C,"DAL",PQ_GL_Data!$E:$E,"5010",PQ_GL_Data!$N:$N,"2025-06") -> 3250.59 | G19: =SUM(D19:F19) -> 13687.41
A20: 5020 | B20: Expert Witness Fees | C20: COGS | D20: =SUMIFS(PQ_GL_Data!$I:$I,PQ_GL_Data!$C:$C,"MIA",PQ_GL_Data!$E:$E,"5020",PQ_GL_Data!$N:$N,"2025-06")-SUMIFS(PQ_GL_Data!$J:$J,PQ_GL_Data!$C:$C,"MIA",PQ_GL_Data!$E:$E,"5020",PQ_GL_Data!$N:$N,"2025-06") -> 5290.92 | E20: =SUMIFS(PQ_GL_Data!$I:$I,PQ_GL_Data!$C:$C,"CHI",PQ_GL_Data!$E:$E,"5020",PQ_GL_Data!$N:$N,"2025-06")-SUMIFS(PQ_GL_Data!$J:$J,PQ_GL_Data!$C:$C,"CHI",PQ_GL_Data!$E:$E,"5020",PQ_GL_Data!$N:$N,"2025-06") -> 3248.29 | F20: =SUMIFS(PQ_GL_Data!$I:$I,PQ_GL_Data!$C:$C,"DAL",PQ_GL_Data!$E:$E,"5020",PQ_GL_Data!$N:$N,"2025-06")-SUMIFS(PQ_GL_Data!$J:$J,PQ_GL_Data!$C:$C,"DAL",PQ_GL_Data!$E:$E,"5020",PQ_GL_Data!$N:$N,"2025-06") -> 2659.57 | G20: =SUM(D20:F20) -> 11198.78
A21: 6000 | B21: Operating Expenses | C21: Opex | D21: =SUMIFS(PQ_GL_Data!$I:$I,PQ_GL_Data!$C:$C,"MIA",PQ_GL_Data!$E:$E,"6000",PQ_GL_Data!$N:$N,"2025-06")-SUMIFS(PQ_GL_Data!$J:$J,PQ_GL_Data!$C:$C,"MIA",PQ_GL_Data!$E:$E,"6000",PQ_GL_Data!$N:$N,"2025-06") -> 0 | E21: =SUMIFS(PQ_GL_Data!$I:$I,PQ_GL_Data!$C:$C,"CHI",PQ_GL_Data!$E:$E,"6000",PQ_GL_Data!$N:$N,"2025-06")-SUMIFS(PQ_GL_Data!$J:$J,PQ_GL_Data!$C:$C,"CHI",PQ_GL_Data!$E:$E,"6000",PQ_GL_Data!$N:$N,"2025-06") -> 0 | F21: =SUMIFS(PQ_GL_Data!$I:$I,PQ_GL_Data!$C:$C,"DAL",PQ_GL_Data!$E:$E,"6000",PQ_GL_Data!$N:$N,"2025-06")-SUMIFS(PQ_GL_Data!$J:$J,PQ_GL_Data!$C:$C,"DAL",PQ_GL_Data!$E:$E,"6000",PQ_GL_Data!$N:$N,"2025-06") -> 0 | G21: =SUM(D21:F21) -> 0
A22: 6010 | B22: Attorney & Staff Payroll | C22: Opex | D22: =SUMIFS(PQ_GL_Data!$I:$I,PQ_GL_Data!$C:$C,"MIA",PQ_GL_Data!$E:$E,"6010",PQ_GL_Data!$N:$N,"2025-06")-SUMIFS(PQ_GL_Data!$J:$J,PQ_GL_Data!$C:$C,"MIA",PQ_GL_Data!$E:$E,"6010",PQ_GL_Data!$N:$N,"2025-06") -> 49364 | E22: =SUMIFS(PQ_GL_Data!$I:$I,PQ_GL_Data!$C:$C,"CHI",PQ_GL_Data!$E:$E,"6010",PQ_GL_Data!$N:$N,"2025-06")-SUMIFS(PQ_GL_Data!$J:$J,PQ_GL_Data!$C:$C,"CHI",PQ_GL_Data!$E:$E,"6010",PQ_GL_Data!$N:$N,"2025-06") -> 30605.68 | F22: =SUMIFS(PQ_GL_Data!$I:$I,PQ_GL_Data!$C:$C,"DAL",PQ_GL_Data!$E:$E,"6010",PQ_GL_Data!$N:$N,"2025-06")-SUMIFS(PQ_GL_Data!$J:$J,PQ_GL_Data!$C:$C,"DAL",PQ_GL_Data!$E:$E,"6010",PQ_GL_Data!$N:$N,"2025-06") -> 27150.2 | G22: =SUM(D22:F22) -> 107119.88
A23: 6020 | B23: Payroll Taxes & Benefits | C23: Opex | D23: =SUMIFS(PQ_GL_Data!$I:$I,PQ_GL_Data!$C:$C,"MIA",PQ_GL_Data!$E:$E,"6020",PQ_GL_Data!$N:$N,"2025-06")-SUMIFS(PQ_GL_Data!$J:$J,PQ_GL_Data!$C:$C,"MIA",PQ_GL_Data!$E:$E,"6020",PQ_GL_Data!$N:$N,"2025-06") -> 6910.96 | E23: =SUMIFS(PQ_GL_Data!$I:$I,PQ_GL_Data!$C:$C,"CHI",PQ_GL_Data!$E:$E,"6020",PQ_GL_Data!$N:$N,"2025-06")-SUMIFS(PQ_GL_Data!$J:$J,PQ_GL_Data!$C:$C,"CHI",PQ_GL_Data!$E:$E,"6020",PQ_GL_Data!$N:$N,"2025-06") -> 4284.8 | F23: =SUMIFS(PQ_GL_Data!$I:$I,PQ_GL_Data!$C:$C,"DAL",PQ_GL_Data!$E:$E,"6020",PQ_GL_Data!$N:$N,"2025-06")-SUMIFS(PQ_GL_Data!$J:$J,PQ_GL_Data!$C:$C,"DAL",PQ_GL_Data!$E:$E,"6020",PQ_GL_Data!$N:$N,"2025-06") -> 3801.03 | G23: =SUM(D23:F23) -> 14996.79
A24: 6030 | B24: Office Rent | C24: Opex | D24: =SUMIFS(PQ_GL_Data!$I:$I,PQ_GL_Data!$C:$C,"MIA",PQ_GL_Data!$E:$E,"6030",PQ_GL_Data!$N:$N,"2025-06")-SUMIFS(PQ_GL_Data!$J:$J,PQ_GL_Data!$C:$C,"MIA",PQ_GL_Data!$E:$E,"6030",PQ_GL_Data!$N:$N,"2025-06") -> 7378 | E24: =SUMIFS(PQ_GL_Data!$I:$I,PQ_GL_Data!$C:$C,"CHI",PQ_GL_Data!$E:$E,"6030",PQ_GL_Data!$N:$N,"2025-06")-SUMIFS(PQ_GL_Data!$J:$J,PQ_GL_Data!$C:$C,"CHI",PQ_GL_Data!$E:$E,"6030",PQ_GL_Data!$N:$N,"2025-06") -> 4574.36 | F24: =SUMIFS(PQ_GL_Data!$I:$I,PQ_GL_Data!$C:$C,"DAL",PQ_GL_Data!$E:$E,"6030",PQ_GL_Data!$N:$N,"2025-06")-SUMIFS(PQ_GL_Data!$J:$J,PQ_GL_Data!$C:$C,"DAL",PQ_GL_Data!$E:$E,"6030",PQ_GL_Data!$N:$N,"2025-06") -> 4057.9 | G24: =SUM(D24:F24) -> 16010.26
A25: 6040 | B25: Marketing & Business Development | C25: Opex | D25: =SUMIFS(PQ_GL_Data!$I:$I,PQ_GL_Data!$C:$C,"MIA",PQ_GL_Data!$E:$E,"6040",PQ_GL_Data!$N:$N,"2025-06")-SUMIFS(PQ_GL_Data!$J:$J,PQ_GL_Data!$C:$C,"MIA",PQ_GL_Data!$E:$E,"6040",PQ_GL_Data!$N:$N,"2025-06") -> 3289.42 | E25: =SUMIFS(PQ_GL_Data!$I:$I,PQ_GL_Data!$C:$C,"CHI",PQ_GL_Data!$E:$E,"6040",PQ_GL_Data!$N:$N,"2025-06")-SUMIFS(PQ_GL_Data!$J:$J,PQ_GL_Data!$C:$C,"CHI",PQ_GL_Data!$E:$E,"6040",PQ_GL_Data!$N:$N,"2025-06") -> 2019.49 | F25: =SUMIFS(PQ_GL_Data!$I:$I,PQ_GL_Data!$C:$C,"DAL",PQ_GL_Data!$E:$E,"6040",PQ_GL_Data!$N:$N,"2025-06")-SUMIFS(PQ_GL_Data!$J:$J,PQ_GL_Data!$C:$C,"DAL",PQ_GL_Data!$E:$E,"6040",PQ_GL_Data!$N:$N,"2025-06") -> 1653.48 | G25: =SUM(D25:F25) -> 6962.39
A26: 6050 | B26: Professional Insurance | C26: Opex | D26: =SUMIFS(PQ_GL_Data!$I:$I,PQ_GL_Data!$C:$C,"MIA",PQ_GL_Data!$E:$E,"6050",PQ_GL_Data!$N:$N,"2025-06")-SUMIFS(PQ_GL_Data!$J:$J,PQ_GL_Data!$C:$C,"MIA",PQ_GL_Data!$E:$E,"6050",PQ_GL_Data!$N:$N,"2025-06") -> 1450 | E26: =SUMIFS(PQ_GL_Data!$I:$I,PQ_GL_Data!$C:$C,"CHI",PQ_GL_Data!$E:$E,"6050",PQ_GL_Data!$N:$N,"2025-06")-SUMIFS(PQ_GL_Data!$J:$J,PQ_GL_Data!$C:$C,"CHI",PQ_GL_Data!$E:$E,"6050",PQ_GL_Data!$N:$N,"2025-06") -> 899 | F26: =SUMIFS(PQ_GL_Data!$I:$I,PQ_GL_Data!$C:$C,"DAL",PQ_GL_Data!$E:$E,"6050",PQ_GL_Data!$N:$N,"2025-06")-SUMIFS(PQ_GL_Data!$J:$J,PQ_GL_Data!$C:$C,"DAL",PQ_GL_Data!$E:$E,"6050",PQ_GL_Data!$N:$N,"2025-06") -> 797.5 | G26: =SUM(D26:F26) -> 3146.5
A27: 6060 | B27: Software & IT | C27: Opex | D27: =SUMIFS(PQ_GL_Data!$I:$I,PQ_GL_Data!$C:$C,"MIA",PQ_GL_Data!$E:$E,"6060",PQ_GL_Data!$N:$N,"2025-06")-SUMIFS(PQ_GL_Data!$J:$J,PQ_GL_Data!$C:$C,"MIA",PQ_GL_Data!$E:$E,"6060",PQ_GL_Data!$N:$N,"2025-06") -> 2457 | E27: =SUMIFS(PQ_GL_Data!$I:$I,PQ_GL_Data!$C:$C,"CHI",PQ_GL_Data!$E:$E,"6060",PQ_GL_Data!$N:$N,"2025-06")-SUMIFS(PQ_GL_Data!$J:$J,PQ_GL_Data!$C:$C,"CHI",PQ_GL_Data!$E:$E,"6060",PQ_GL_Data!$N:$N,"2025-06") -> 1523.34 | F27: =SUMIFS(PQ_GL_Data!$I:$I,PQ_GL_Data!$C:$C,"DAL",PQ_GL_Data!$E:$E,"6060",PQ_GL_Data!$N:$N,"2025-06")-SUMIFS(PQ_GL_Data!$J:$J,PQ_GL_Data!$C:$C,"DAL",PQ_GL_Data!$E:$E,"6060",PQ_GL_Data!$N:$N,"2025-06") -> 1351.35 | G27: =SUM(D27:F27) -> 5331.69
A28: 6070 | B28: Shared Services Allocation (Intercompany) | C28: Opex | D28: =SUMIFS(PQ_GL_Data!$I:$I,PQ_GL_Data!$C:$C,"MIA",PQ_GL_Data!$E:$E,"6070",PQ_GL_Data!$N:$N,"2025-06")-SUMIFS(PQ_GL_Data!$J:$J,PQ_GL_Data!$C:$C,"MIA",PQ_GL_Data!$E:$E,"6070",PQ_GL_Data!$N:$N,"2025-06") -> 0 | E28: =SUMIFS(PQ_GL_Data!$I:$I,PQ_GL_Data!$C:$C,"CHI",PQ_GL_Data!$E:$E,"6070",PQ_GL_Data!$N:$N,"2025-06")-SUMIFS(PQ_GL_Data!$J:$J,PQ_GL_Data!$C:$C,"CHI",PQ_GL_Data!$E:$E,"6070",PQ_GL_Data!$N:$N,"2025-06") -> 3772.08 | F28: =SUMIFS(PQ_GL_Data!$I:$I,PQ_GL_Data!$C:$C,"DAL",PQ_GL_Data!$E:$E,"6070",PQ_GL_Data!$N:$N,"2025-06")-SUMIFS(PQ_GL_Data!$J:$J,PQ_GL_Data!$C:$C,"DAL",PQ_GL_Data!$E:$E,"6070",PQ_GL_Data!$N:$N,"2025-06") -> 3346.2 | G28: =SUM(D28:F28) -> 7118.28
A29: 7000 | B29: Depreciation Expense | C29: Opex | D29: =SUMIFS(PQ_GL_Data!$I:$I,PQ_GL_Data!$C:$C,"MIA",PQ_GL_Data!$E:$E,"7000",PQ_GL_Data!$N:$N,"2025-06")-SUMIFS(PQ_GL_Data!$J:$J,PQ_GL_Data!$C:$C,"MIA",PQ_GL_Data!$E:$E,"7000",PQ_GL_Data!$N:$N,"2025-06") -> 1100 | E29: =SUMIFS(PQ_GL_Data!$I:$I,PQ_GL_Data!$C:$C,"CHI",PQ_GL_Data!$E:$E,"7000",PQ_GL_Data!$N:$N,"2025-06")-SUMIFS(PQ_GL_Data!$J:$J,PQ_GL_Data!$C:$C,"CHI",PQ_GL_Data!$E:$E,"7000",PQ_GL_Data!$N:$N,"2025-06") -> 682 | F29: =SUMIFS(PQ_GL_Data!$I:$I,PQ_GL_Data!$C:$C,"DAL",PQ_GL_Data!$E:$E,"7000",PQ_GL_Data!$N:$N,"2025-06")-SUMIFS(PQ_GL_Data!$J:$J,PQ_GL_Data!$C:$C,"DAL",PQ_GL_Data!$E:$E,"7000",PQ_GL_Data!$N:$N,"2025-06") -> 605 | G29: =SUM(D29:F29) -> 2387
A30: 8000 | B30: Interest Expense | C30: Opex | D30: =SUMIFS(PQ_GL_Data!$I:$I,PQ_GL_Data!$C:$C,"MIA",PQ_GL_Data!$E:$E,"8000",PQ_GL_Data!$N:$N,"2025-06")-SUMIFS(PQ_GL_Data!$J:$J,PQ_GL_Data!$C:$C,"MIA",PQ_GL_Data!$E:$E,"8000",PQ_GL_Data!$N:$N,"2025-06") -> 0 | E30: =SUMIFS(PQ_GL_Data!$I:$I,PQ_GL_Data!$C:$C,"CHI",PQ_GL_Data!$E:$E,"8000",PQ_GL_Data!$N:$N,"2025-06")-SUMIFS(PQ_GL_Data!$J:$J,PQ_GL_Data!$C:$C,"CHI",PQ_GL_Data!$E:$E,"8000",PQ_GL_Data!$N:$N,"2025-06") -> 0 | F30: =SUMIFS(PQ_GL_Data!$I:$I,PQ_GL_Data!$C:$C,"DAL",PQ_GL_Data!$E:$E,"8000",PQ_GL_Data!$N:$N,"2025-06")-SUMIFS(PQ_GL_Data!$J:$J,PQ_GL_Data!$C:$C,"DAL",PQ_GL_Data!$E:$E,"8000",PQ_GL_Data!$N:$N,"2025-06") -> 0 | G30: =SUM(D30:F30) -> 0

Sheet Bank_Reconciliation
A1: Bank Reconciliation — Cash Account — 2025-06
A3: Line Item | B3: MIA | C3: CHI | D3: DAL
A4: Book Cash Movement (per GL, account 1000) | B4: =SUMIFS(PQ_GL_Data!$I:$I,PQ_GL_Data!$C:$C,"MIA",PQ_GL_Data!$E:$E,"1000",PQ_GL_Data!$N:$N,"2025-06")-SUMIFS(PQ_GL_Data!$J:$J,PQ_GL_Data!$C:$C,"MIA",PQ_GL_Data!$E:$E,"1000",PQ_GL_Data!$N:$N,"2025-06") -> 33024.53 | C4: =SUMIFS(PQ_GL_Data!$I:$I,PQ_GL_Data!$C:$C,"CHI",PQ_GL_Data!$E:$E,"1000",PQ_GL_Data!$N:$N,"2025-06")-SUMIFS(PQ_GL_Data!$J:$J,PQ_GL_Data!$C:$C,"CHI",PQ_GL_Data!$E:$E,"1000",PQ_GL_Data!$N:$N,"2025-06") -> 10400.85 | D4: =SUMIFS(PQ_GL_Data!$I:$I,PQ_GL_Data!$C:$C,"DAL",PQ_GL_Data!$E:$E,"1000",PQ_GL_Data!$N:$N,"2025-06")-SUMIFS(PQ_GL_Data!$J:$J,PQ_GL_Data!$C:$C,"DAL",PQ_GL_Data!$E:$E,"1000",PQ_GL_Data!$N:$N,"2025-06") -> 7680.73
A5: Add: Bank-identified items not yet booked (fees, interest) | B5: =SUMIFS(PQ_Bank_Data!$D:$D,PQ_Bank_Data!$B:$B,"MIA",PQ_Bank_Data!$H:$H,"2025-06",PQ_Bank_Data!$F:$F,"Unmatched - Book Adjustment Needed") -> -10 | C5: =SUMIFS(PQ_Bank_Data!$D:$D,PQ_Bank_Data!$B:$B,"CHI",PQ_Bank_Data!$H:$H,"2025-06",PQ_Bank_Data!$F:$F,"Unmatched - Book Adjustment Needed") -> -12.66 | D5: =SUMIFS(PQ_Bank_Data!$D:$D,PQ_Bank_Data!$B:$B,"DAL",PQ_Bank_Data!$H:$H,"2025-06",PQ_Bank_Data!$F:$F,"Unmatched - Book Adjustment Needed") -> -13.15
A6: Adjusted Book Balance | B6: =B4+B5 -> 33014.53 | C6: =C4+C5 -> 10388.19 | D6: =D4+D5 -> 7667.58
A8: Bank Statement Movement | B8: =SUMIFS(PQ_Bank_Data!$D:$D,PQ_Bank_Data!$B:$B,"MIA",PQ_Bank_Data!$H:$H,"2025-06") -> 35646.07 | C8: =SUMIFS(PQ_Bank_Data!$D:$D,PQ_Bank_Data!$B:$B,"CHI",PQ_Bank_Data!$H:$H,"2025-06") -> 12003.78 | D8: =SUMIFS(PQ_Bank_Data!$D:$D,PQ_Bank_Data!$B:$B,"DAL",PQ_Bank_Data!$H:$H,"2025-06") -> 8990.36
A9: Add: Outstanding items (book not yet cleared bank) | B9: =B4-(SUMIFS(PQ_Bank_Data!$D:$D,PQ_Bank_Data!$B:$B,"MIA",PQ_Bank_Data!$H:$H,"2025-06",PQ_Bank_Data!$F:$F,"Matched")) -> -2631.54 | C9: =C4-(SUMIFS(PQ_Bank_Data!$D:$D,PQ_Bank_Data!$B:$B,"CHI",PQ_Bank_Data!$H:$H,"2025-06",PQ_Bank_Data!$F:$F,"Matched")) -> -1615.59 | D9: =D4-(SUMIFS(PQ_Bank_Data!$D:$D,PQ_Bank_Data!$B:$B,"DAL",PQ_Bank_Data!$H:$H,"2025-06",PQ_Bank_Data!$F:$F,"Matched")) -> -1322.78
A10: Adjusted Bank Balance | B10: =B8+B9 -> 33014.53 | C10: =C8+C9 -> 10388.19 | D10: =D8+D9 -> 7667.58
A12: Difference (Adjusted Book − Adjusted Bank) | B12: =B6-B10 -> 0 | C12: =C6-C10 -> 0 | D12: =D6-D10 -> 0

Sheet Consolidation
A1: Group Consolidation — P&L — 2025-06
A3: Line Item | B3: MIA | C3: CHI | D3: DAL | E3: Combined
A4: External Legal Fee Revenue | B4: =SUMIFS(PQ_GL_Data!$J:$J,PQ_GL_Data!$C:$C,"MIA",PQ_GL_Data!$G:$G,"Revenue",PQ_GL_Data!$H:$H,"No",PQ_GL_Data!$N:$N,"2025-06")-SUMIFS(PQ_GL_Data!$I:$I,PQ_GL_Data!$C:$C,"MIA",PQ_GL_Data!$G:$G,"Revenue",PQ_GL_Data!$H:$H,"No",PQ_GL_Data!$N:$N,"2025-06") -> 113863.1 | C4: =SUMIFS(PQ_GL_Data!$J:$J,PQ_GL_Data!$C:$C,"CHI",PQ_GL_Data!$G:$G,"Revenue",PQ_GL_Data!$H:$H,"No",PQ_GL_Data!$N:$N,"2025-06")-SUMIFS(PQ_GL_Data!$I:$I,PQ_GL_Data!$C:$C,"CHI",PQ_GL_Data!$G:$G,"Revenue",PQ_GL_Data!$H:$H,"No",PQ_GL_Data!$N:$N,"2025-06") -> 69904.78 | D4: =SUMIFS(PQ_GL_Data!$J:$J,PQ_GL_Data!$C:$C,"DAL",PQ_GL_Data!$G:$G,"Revenue",PQ_GL_Data!$H:$H,"No",PQ_GL_Data!$N:$N,"2025-06")-SUMIFS(PQ_GL_Data!$I:$I,PQ_GL_Data!$C:$C,"DAL",PQ_GL_Data!$G:$G,"Revenue",PQ_GL_Data!$H:$H,"No",PQ_GL_Data!$N:$N,"2025-06") -> 57235.2 | E4: =SUM(B4:D4) -> 241003.08
A5: Intercompany Shared Services Revenue | B5: =SUMIFS(PQ_GL_Data!$J:$J,PQ_GL_Data!$C:$C,"MIA",PQ_GL_Data!$G:$G,"Revenue",PQ_GL_Data!$H:$H,"Yes",PQ_GL_Data!$N:$N,"2025-06")-SUMIFS(PQ_GL_Data!$I:$I,PQ_GL_Data!$C:$C,"MIA",PQ_GL_Data!$G:$G,"Revenue",PQ_GL_Data!$H:$H,"Yes",PQ_GL_Data!$N:$N,"2025-06") -> 7118.28 | C5: =SUMIFS(PQ_GL_Data!$J:$J,PQ_GL_Data!$C:$C,"CHI",PQ_GL_Data!$G:$G,"Revenue",PQ_GL_Data!$H:$H,"Yes",PQ_GL_Data!$N:$N,"2025-06")-SUMIFS(PQ_GL_Data!$I:$I,PQ_GL_Data!$C:$C,"CHI",PQ_GL_Data!$G:$G,"Revenue",PQ_GL_Data!$H:$H,"Yes",PQ_GL_Data!$N:$N,"2025-06") -> 0 | D5: =SUMIFS(PQ_GL_Data!$J:$J,PQ_GL_Data!$C:$C,"DAL",PQ_GL_Data!$G:$G,"Revenue",PQ_GL_Data!$H:$H,"Yes",PQ_GL_Data!$N:$N,"2025-06")-SUMIFS(PQ_GL_Data!$I:$I,PQ_GL_Data!$C:$C,"DAL",PQ_GL_Data!$G:$G,"Revenue",PQ_GL_Data!$H:$H,"Yes",PQ_GL_Data!$N:$N,"2025-06") -> 0 | E5: =SUM(B5:D5) -> 7118.28
A6: Total Revenue (Gross) | B6: =B4+B5 -> 120981.38 | C6: =C4+C5 -> 69904.78 | D6: =D4+D5 -> 57235.2 | E6: =E4+E5 -> 248121.36
A7: Direct Case Costs (COGS) | B7: =SUMIFS(PQ_GL_Data!$I:$I,PQ_GL_Data!$C:$C,"MIA",PQ_GL_Data!$G:$G,"COGS",PQ_GL_Data!$N:$N,"2025-06")-SUMIFS(PQ_GL_Data!$J:$J,PQ_GL_Data!$C:$C,"MIA",PQ_GL_Data!$G:$G,"COGS",PQ_GL_Data!$N:$N,"2025-06") -> 11757.6 | C7: =SUMIFS(PQ_GL_Data!$I:$I,PQ_GL_Data!$C:$C,"CHI",PQ_GL_Data!$G:$G,"COGS",PQ_GL_Data!$N:$N,"2025-06")-SUMIFS(PQ_GL_Data!$J:$J,PQ_GL_Data!$C:$C,"CHI",PQ_GL_Data!$G:$G,"COGS",PQ_GL_Data!$N:$N,"2025-06") -> 7218.43 | D7: =SUMIFS(PQ_GL_Data!$I:$I,PQ_GL_Data!$C:$C,"DAL",PQ_GL_Data!$G:$G,"COGS",PQ_GL_Data!$N:$N,"2025-06")-SUMIFS(PQ_GL_Data!$J:$J,PQ_GL_Data!$C:$C,"DAL",PQ_GL_Data!$G:$G,"COGS",PQ_GL_Data!$N:$N,"2025-06") -> 5910.16 | E7: =SUM(B7:D7) -> 24886.19
A8: Gross Profit | B8: =B6-B7 -> 109223.78 | C8: =C6-C7 -> 62686.35 | D8: =D6-D7 -> 51325.04 | E8: =E6-E7 -> 223235.17
A10: Attorney & Staff Payroll | B10: =SUMIFS(PQ_GL_Data!$I:$I,PQ_GL_Data!$C:$C,"MIA",PQ_GL_Data!$E:$E,"6010",PQ_GL_Data!$N:$N,"2025-06")-SUMIFS(PQ_GL_Data!$J:$J,PQ_GL_Data!$C:$C,"MIA",PQ_GL_Data!$E:$E,"6010",PQ_GL_Data!$N:$N,"2025-06") -> 49364 | C10: =SUMIFS(PQ_GL_Data!$I:$I,PQ_GL_Data!$C:$C,"CHI",PQ_GL_Data!$E:$E,"6010",PQ_GL_Data!$N:$N,"2025-06")-SUMIFS(PQ_GL_Data!$J:$J,PQ_GL_Data!$C:$C,"CHI",PQ_GL_Data!$E:$E,"6010",PQ_GL_Data!$N:$N,"2025-06") -> 30605.68 | D10: =SUMIFS(PQ_GL_Data!$I:$I,PQ_GL_Data!$C:$C,"DAL",PQ_GL_Data!$E:$E,"6010",PQ_GL_Data!$N:$N,"2025-06")-SUMIFS(PQ_GL_Data!$J:$J,PQ_GL_Data!$C:$C,"DAL",PQ_GL_Data!$E:$E,"6010",PQ_GL_Data!$N:$N,"2025-06") -> 27150.2 | E10: =SUM(B10:D10) -> 107119.88
A11: Payroll Taxes & Benefits | B11: =SUMIFS(PQ_GL_Data!$I:$I,PQ_GL_Data!$C:$C,"MIA",PQ_GL_Data!$E:$E,"6020",PQ_GL_Data!$N:$N,"2025-06")-SUMIFS(PQ_GL_Data!$J:$J,PQ_GL_Data!$C:$C,"MIA",PQ_GL_Data!$E:$E,"6020",PQ_GL_Data!$N:$N,"2025-06") -> 6910.96 | C11: =SUMIFS(PQ_GL_Data!$I:$I,PQ_GL_Data!$C:$C,"CHI",PQ_GL_Data!$E:$E,"6020",PQ_GL_Data!$N:$N,"2025-06")-SUMIFS(PQ_GL_Data!$J:$J,PQ_GL_Data!$C:$C,"CHI",PQ_GL_Data!$E:$E,"6020",PQ_GL_Data!$N:$N,"2025-06") -> 4284.8 | D11: =SUMIFS(PQ_GL_Data!$I:$I,PQ_GL_Data!$C:$C,"DAL",PQ_GL_Data!$E:$E,"6020",PQ_GL_Data!$N:$N,"2025-06")-SUMIFS(PQ_GL_Data!$J:$J,PQ_GL_Data!$C:$C,"DAL",PQ_GL_Data!$E:$E,"6020",PQ_GL_Data!$N:$N,"2025-06") -> 3801.03 | E11: =SUM(B11:D11) -> 14996.79
A12: Office Rent | B12: =SUMIFS(PQ_GL_Data!$I:$I,PQ_GL_Data!$C:$C,"MIA",PQ_GL_Data!$E:$E,"6030",PQ_GL_Data!$N:$N,"2025-06")-SUMIFS(PQ_GL_Data!$J:$J,PQ_GL_Data!$C:$C,"MIA",PQ_GL_Data!$E:$E,"6030",PQ_GL_Data!$N:$N,"2025-06") -> 7378 | C12: =SUMIFS(PQ_GL_Data!$I:$I,PQ_GL_Data!$C:$C,"CHI",PQ_GL_Data!$E:$E,"6030",PQ_GL_Data!$N:$N,"2025-06")-SUMIFS(PQ_GL_Data!$J:$J,PQ_GL_Data!$C:$C,"CHI",PQ_GL_Data!$E:$E,"6030",PQ_GL_Data!$N:$N,"2025-06") -> 4574.36 | D12: =SUMIFS(PQ_GL_Data!$I:$I,PQ_GL_Data!$C:$C,"DAL",PQ_GL_Data!$E:$E,"6030",PQ_GL_Data!$N:$N,"2025-06")-SUMIFS(PQ_GL_Data!$J:$J,PQ_GL_Data!$C:$C,"DAL",PQ_GL_Data!$E:$E,"6030",PQ_GL_Data!$N:$N,"2025-06") -> 4057.9 | E12: =SUM(B12:D12) -> 16010.26
A13: Marketing & Business Development | B13: =SUMIFS(PQ_GL_Data!$I:$I,PQ_GL_Data!$C:$C,"MIA",PQ_GL_Data!$E:$E,"6040",PQ_GL_Data!$N:$N,"2025-06")-SUMIFS(PQ_GL_Data!$J:$J,PQ_GL_Data!$C:$C,"MIA",PQ_GL_Data!$E:$E,"6040",PQ_GL_Data!$N:$N,"2025-06") -> 3289.42 | C13: =SUMIFS(PQ_GL_Data!$I:$I,PQ_GL_Data!$C:$C,"CHI",PQ_GL_Data!$E:$E,"6040",PQ_GL_Data!$N:$N,"2025-06")-SUMIFS(PQ_GL_Data!$J:$J,PQ_GL_Data!$C:$C,"CHI",PQ_GL_Data!$E:$E,"6040",PQ_GL_Data!$N:$N,"2025-06") -> 2019.49 | D13: =SUMIFS(PQ_GL_Data!$I:$I,PQ_GL_Data!$C:$C,"DAL",PQ_GL_Data!$E:$E,"6040",PQ_GL_Data!$N:$N,"2025-06")-SUMIFS(PQ_GL_Data!$J:$J,PQ_GL_Data!$C:$C,"DAL",PQ_GL_Data!$E:$E,"6040",PQ_GL_Data!$N:$N,"2025-06") -> 1653.48 | E13: =SUM(B13:D13) -> 6962.39
A14: Professional Insurance | B14: =SUMIFS(PQ_GL_Data!$I:$I,PQ_GL_Data!$C:$C,"MIA",PQ_GL_Data!$E:$E,"6050",PQ_GL_Data!$N:$N,"2025-06")-SUMIFS(PQ_GL_Data!$J:$J,PQ_GL_Data!$C:$C,"MIA",PQ_GL_Data!$E:$E,"6050",PQ_GL_Data!$N:$N,"2025-06") -> 1450 | C14: =SUMIFS(PQ_GL_Data!$I:$I,PQ_GL_Data!$C:$C,"CHI",PQ_GL_Data!$E:$E,"6050",PQ_GL_Data!$N:$N,"2025-06")-SUMIFS(PQ_GL_Data!$J:$J,PQ_GL_Data!$C:$C,"CHI",PQ_GL_Data!$E:$E,"6050",PQ_GL_Data!$N:$N,"2025-06") -> 899 | D14: =SUMIFS(PQ_GL_Data!$I:$I,PQ_GL_Data!$C:$C,"DAL",PQ_GL_Data!$E:$E,"6050",PQ_GL_Data!$N:$N,"2025-06")-SUMIFS(PQ_GL_Data!$J:$J,PQ_GL_Data!$C:$C,"DAL",PQ_GL_Data!$E:$E,"6050",PQ_GL_Data!$N:$N,"2025-06") -> 797.5 | E14: =SUM(B14:D14) -> 3146.5
A15: Software & IT | B15: =SUMIFS(PQ_GL_Data!$I:$I,PQ_GL_Data!$C:$C,"MIA",PQ_GL_Data!$E:$E,"6060",PQ_GL_Data!$N:$N,"2025-06")-SUMIFS(PQ_GL_Data!$J:$J,PQ_GL_Data!$C:$C,"MIA",PQ_GL_Data!$E:$E,"6060",PQ_GL_Data!$N:$N,"2025-06") -> 2457 | C15: =SUMIFS(PQ_GL_Data!$I:$I,PQ_GL_Data!$C:$C,"CHI",PQ_GL_Data!$E:$E,"6060",PQ_GL_Data!$N:$N,"2025-06")-SUMIFS(PQ_GL_Data!$J:$J,PQ_GL_Data!$C:$C,"CHI",PQ_GL_Data!$E:$E,"6060",PQ_GL_Data!$N:$N,"2025-06") -> 1523.34 | D15: =SUMIFS(PQ_GL_Data!$I:$I,PQ_GL_Data!$C:$C,"DAL",PQ_GL_Data!$E:$E,"6060",PQ_GL_Data!$N:$N,"2025-06")-SUMIFS(PQ_GL_Data!$J:$J,PQ_GL_Data!$C:$C,"DAL",PQ_GL_Data!$E:$E,"6060",PQ_GL_Data!$N:$N,"2025-06") -> 1351.35 | E15: =SUM(B15:D15) -> 5331.69
A16: Shared Services Allocation (Intercompany) | B16: =SUMIFS(PQ_GL_Data!$I:$I,PQ_GL_Data!$C:$C,"MIA",PQ_GL_Data!$E:$E,"6070",PQ_GL_Data!$N:$N,"2025-06")-SUMIFS(PQ_GL_Data!$J:$J,PQ_GL_Data!$C:$C,"MIA",PQ_GL_Data!$E:$E,"6070",PQ_GL_Data!$N:$N,"2025-06") -> 0 | C16: =SUMIFS(PQ_GL_Data!$I:$I,PQ_GL_Data!$C:$C,"CHI",PQ_GL_Data!$E:$E,"6070",PQ_GL_Data!$N:$N,"2025-06")-SUMIFS(PQ_GL_Data!$J:$J,PQ_GL_Data!$C:$C,"CHI",PQ_GL_Data!$E:$E,"6070",PQ_GL_Data!$N:$N,"2025-06") -> 3772.08 | D16: =SUMIFS(PQ_GL_Data!$I:$I,PQ_GL_Data!$C:$C,"DAL",PQ_GL_Data!$E:$E,"6070",PQ_GL_Data!$N:$N,"2025-06")-SUMIFS(PQ_GL_Data!$J:$J,PQ_GL_Data!$C:$C,"DAL",PQ_GL_Data!$E:$E,"6070",PQ_GL_Data!$N:$N,"2025-06") -> 3346.2 | E16: =SUM(B16:D16) -> 7118.28
A17: Depreciation Expense | B17: =SUMIFS(PQ_GL_Data!$I:$I,PQ_GL_Data!$C:$C,"MIA",PQ_GL_Data!$E:$E,"7000",PQ_GL_Data!$N:$N,"2025-06")-SUMIFS(PQ_GL_Data!$J:$J,PQ_GL_Data!$C:$C,"MIA",PQ_GL_Data!$E:$E,"7000",PQ_GL_Data!$N:$N,"2025-06") -> 1100 | C17: =SUMIFS(PQ_GL_Data!$I:$I,PQ_GL_Data!$C:$C,"CHI",PQ_GL_Data!$E:$E,"7000",PQ_GL_Data!$N:$N,"2025-06")-SUMIFS(PQ_GL_Data!$J:$J,PQ_GL_Data!$C:$C,"CHI",PQ_GL_Data!$E:$E,"7000",PQ_GL_Data!$N:$N,"2025-06") -> 682 | D17: =SUMIFS(PQ_GL_Data!$I:$I,PQ_GL_Data!$C:$C,"DAL",PQ_GL_Data!$E:$E,"7000",PQ_GL_Data!$N:$N,"2025-06")-SUMIFS(PQ_GL_Data!$J:$J,PQ_GL_Data!$C:$C,"DAL",PQ_GL_Data!$E:$E,"7000",PQ_GL_Data!$N:$N,"2025-06") -> 605 | E17: =SUM(B17:D17) -> 2387
A18: Total Operating Expenses (Gross) | B18: =B10+B11+B12+B13+B14+B15+B16+B17 -> 71949.38 | C18: =C10+C11+C12+C13+C14+C15+C16+C17 -> 48360.75 | D18: =D10+D11+D12+D13+D14+D15+D16+D17 -> 42762.66 | E18: =E10+E11+E12+E13+E14+E15+E16+E17 -> 163072.79
A19: Operating Income (Combined, Pre-Elimination) | B19: =B8-B18 -> 37274.4 | C19: =C8-C18 -> 14325.6 | D19: =D8-D18 -> 8562.38 | E19: =E8-E18 -> 60162.38
A21: Consolidation Adjustments
A22: Eliminate: Intercompany Shared Services Revenue | E22: =-E5 -> -7118.28
A23: Eliminate: Intercompany Shared Services Allocation | E23: =-E16 -> -7118.28
A25: Total Revenue (Net of Eliminations) | E25: =E6+E22 -> 241003.08
A26: Total Operating Expenses (Net of Eliminations) | E26: =E18+E23 -> 155954.51
A28: Operating Income (Group, Consolidated) | E28: =E25-E7-E26 -> 60162.38
A30: Note: eliminating the intercompany shared-services billing reduces both Group revenue and Group operating expense by the same amount, so it does not change Operating Income - there is no markup on the intercompany charge. The elimination still matters: without it, Group revenue and expense are both overstated, which misleads any margin-% or expense-ratio analysis.

Sheet Budget_vs_Actual
A1: Budget vs. Actual — 2025-06
A3: Entity | B3: Account | C3: Budget | D3: Actual | E3: Variance (Actual - Budget) | F3: % Variance | G3: Overspend Rank
A4: MIA | B4: 4010 Litigation Fees | C4: =SUMIFS(PQ_Budget_Data!$F:$F,PQ_Budget_Data!$B:$B,"MIA",PQ_Budget_Data!$D:$D,"4010",PQ_Budget_Data!$G:$G,"2025-06") -> 46738.17 | D4: =SUMIFS(PQ_GL_Data!$J:$J,PQ_GL_Data!$C:$C,"MIA",PQ_GL_Data!$E:$E,"4010",PQ_GL_Data!$N:$N,"2025-06")-SUMIFS(PQ_GL_Data!$I:$I,PQ_GL_Data!$C:$C,"MIA",PQ_GL_Data!$E:$E,"4010",PQ_GL_Data!$N:$N,"2025-06") -> 47822.5 | E4: =D4-C4 -> 1084.33 | F4: =IFERROR(E4/C4,0) -> 0.023200095 | G4: =RANK(E4,$E$4:$E$35,0) -> 3
A5: MIA | B5: 4020 Corporate & Transactional Fees | C5: =SUMIFS(PQ_Budget_Data!$F:$F,PQ_Budget_Data!$B:$B,"MIA",PQ_Budget_Data!$D:$D,"4020",PQ_Budget_Data!$G:$G,"2025-06") -> 36939.51 | D5: =SUMIFS(PQ_GL_Data!$J:$J,PQ_GL_Data!$C:$C,"MIA",PQ_GL_Data!$E:$E,"4020",PQ_GL_Data!$N:$N,"2025-06")-SUMIFS(PQ_GL_Data!$I:$I,PQ_GL_Data!$C:$C,"MIA",PQ_GL_Data!$E:$E,"4020",PQ_GL_Data!$N:$N,"2025-06") -> 37574.82 | E5: =D5-C5 -> 635.31 | F5: =IFERROR(E5/C5,0) -> 0.017198658 | G5: =RANK(E5,$E$4:$E$35,0) -> 7
A6: MIA | B6: 4030 Family Law Fees | C6: =SUMIFS(PQ_Budget_Data!$F:$F,PQ_Budget_Data!$B:$B,"MIA",PQ_Budget_Data!$D:$D,"4030",PQ_Budget_Data!$G:$G,"2025-06") -> 27684.41 | D6: =SUMIFS(PQ_GL_Data!$J:$J,PQ_GL_Data!$C:$C,"MIA",PQ_GL_Data!$E:$E,"4030",PQ_GL_Data!$N:$N,"2025-06")-SUMIFS(PQ_GL_Data!$I:$I,PQ_GL_Data!$C:$C,"MIA",PQ_GL_Data!$E:$E,"4030",PQ_GL_Data!$N:$N,"2025-06") -> 28465.78 | E6: =D6-C6 -> 781.37 | F6: =IFERROR(E6/C6,0) -> 0.028224188 | G6: =RANK(E6,$E$4:$E$35,0) -> 5
A7: MIA | B7: 6010 Attorney & Staff Payroll | C7: =SUMIFS(PQ_Budget_Data!$F:$F,PQ_Budget_Data!$B:$B,"MIA",PQ_Budget_Data!$D:$D,"6010",PQ_Budget_Data!$G:$G,"2025-06") -> 48699.54 | D7: =SUMIFS(PQ_GL_Data!$I:$I,PQ_GL_Data!$C:$C,"MIA",PQ_GL_Data!$E:$E,"6010",PQ_GL_Data!$N:$N,"2025-06")-SUMIFS(PQ_GL_Data!$J:$J,PQ_GL_Data!$C:$C,"MIA",PQ_GL_Data!$E:$E,"6010",PQ_GL_Data!$N:$N,"2025-06") -> 49364 | E7: =D7-C7 -> 664.46 | F7: =IFERROR(E7/C7,0) -> 0.013644071 | G7: =RANK(E7,$E$4:$E$35,0) -> 6
A8: MIA | B8: 6020 Payroll Taxes & Benefits | C8: =SUMIFS(PQ_Budget_Data!$F:$F,PQ_Budget_Data!$B:$B,"MIA",PQ_Budget_Data!$D:$D,"6020",PQ_Budget_Data!$G:$G,"2025-06") -> 6946.5 | D8: =SUMIFS(PQ_GL_Data!$I:$I,PQ_GL_Data!$C:$C,"MIA",PQ_GL_Data!$E:$E,"6020",PQ_GL_Data!$N:$N,"2025-06")-SUMIFS(PQ_GL_Data!$J:$J,PQ_GL_Data!$C:$C,"MIA",PQ_GL_Data!$E:$E,"6020",PQ_GL_Data!$N:$N,"2025-06") -> 6910.96 | E8: =D8-C8 -> -35.54 | F8: =IFERROR(E8/C8,0) -> -0.0051162456 | G8: =RANK(E8,$E$4:$E$35,0) -> 27
A9: MIA | B9: 6030 Office Rent | C9: =SUMIFS(PQ_Budget_Data!$F:$F,PQ_Budget_Data!$B:$B,"MIA",PQ_Budget_Data!$D:$D,"6030",PQ_Budget_Data!$G:$G,"2025-06") -> 7310.39 | D9: =SUMIFS(PQ_GL_Data!$I:$I,PQ_GL_Data!$C:$C,"MIA",PQ_GL_Data!$E:$E,"6030",PQ_GL_Data!$N:$N,"2025-06")-SUMIFS(PQ_GL_Data!$J:$J,PQ_GL_Data!$C:$C,"MIA",PQ_GL_Data!$E:$E,"6030",PQ_GL_Data!$N:$N,"2025-06") -> 7378 | E9: =D9-C9 -> 67.61 | F9: =IFERROR(E9/C9,0) -> 0.0092484806 | G9: =RANK(E9,$E$4:$E$35,0) -> 13
A10: MIA | B10: 6040 Marketing & Business Development | C10: =SUMIFS(PQ_Budget_Data!$F:$F,PQ_Budget_Data!$B:$B,"MIA",PQ_Budget_Data!$D:$D,"6040",PQ_Budget_Data!$G:$G,"2025-06") -> 3044.1 | D10: =SUMIFS(PQ_GL_Data!$I:$I,PQ_GL_Data!$C:$C,"MIA",PQ_GL_Data!$E:$E,"6040",PQ_GL_Data!$N:$N,"2025-06")-SUMIFS(PQ_GL_Data!$J:$J,PQ_GL_Data!$C:$C,"MIA",PQ_GL_Data!$E:$E,"6040",PQ_GL_Data!$N:$N,"2025-06") -> 3289.42 | E10: =D10-C10 -> 245.32 | F10: =IFERROR(E10/C10,0) -> 0.08058868 | G10: =RANK(E10,$E$4:$E$35,0) -> 10
A11: MIA | B11: 6050 Professional Insurance | C11: =SUMIFS(PQ_Budget_Data!$F:$F,PQ_Budget_Data!$B:$B,"MIA",PQ_Budget_Data!$D:$D,"6050",PQ_Budget_Data!$G:$G,"2025-06") -> 1428 | D11: =SUMIFS(PQ_GL_Data!$I:$I,PQ_GL_Data!$C:$C,"MIA",PQ_GL_Data!$E:$E,"6050",PQ_GL_Data!$N:$N,"2025-06")-SUMIFS(PQ_GL_Data!$J:$J,PQ_GL_Data!$C:$C,"MIA",PQ_GL_Data!$E:$E,"6050",PQ_GL_Data!$N:$N,"2025-06") -> 1450 | E11: =D11-C11 -> 22 | F11: =IFERROR(E11/C11,0) -> 0.015406162 | G11: =RANK(E11,$E$4:$E$35,0) -> 17
A12: MIA | B12: 6060 Software & IT | C12: =SUMIFS(PQ_Budget_Data!$F:$F,PQ_Budget_Data!$B:$B,"MIA",PQ_Budget_Data!$D:$D,"6060",PQ_Budget_Data!$G:$G,"2025-06") -> 2381.47 | D12: =SUMIFS(PQ_GL_Data!$I:$I,PQ_GL_Data!$C:$C,"MIA",PQ_GL_Data!$E:$E,"6060",PQ_GL_Data!$N:$N,"2025-06")-SUMIFS(PQ_GL_Data!$J:$J,PQ_GL_Data!$C:$C,"MIA",PQ_GL_Data!$E:$E,"6060",PQ_GL_Data!$N:$N,"2025-06") -> 2457 | E12: =D12-C12 -> 75.53 | F12: =IFERROR(E12/C12,0) -> 0.031715705 | G12: =RANK(E12,$E$4:$E$35,0) -> 12
A13: MIA | B13: 7000 Depreciation Expense | C13: =SUMIFS(PQ_Budget_Data!$F:$F,PQ_Budget_Data!$B:$B,"MIA",PQ_Budget_Data!$D:$D,"7000",PQ_Budget_Data!$G:$G,"2025-06") -> 1083.26 | D13: =SUMIFS(PQ_GL_Data!$I:$I,PQ_GL_Data!$C:$C,"MIA",PQ_GL_Data!$E:$E,"7000",PQ_GL_Data!$N:$N,"2025-06")-SUMIFS(PQ_GL_Data!$J:$J,PQ_GL_Data!$C:$C,"MIA",PQ_GL_Data!$E:$E,"7000",PQ_GL_Data!$N:$N,"2025-06") -> 1100 | E13: =D13-C13 -> 16.74 | F13: =IFERROR(E13/C13,0) -> 0.015453354 | G13: =RANK(E13,$E$4:$E$35,0) -> 18
A14: CHI | B14: 4010 Litigation Fees | C14: =SUMIFS(PQ_Budget_Data!$F:$F,PQ_Budget_Data!$B:$B,"CHI",PQ_Budget_Data!$D:$D,"4010",PQ_Budget_Data!$G:$G,"2025-06") -> 29542.6 | D14: =SUMIFS(PQ_GL_Data!$J:$J,PQ_GL_Data!$C:$C,"CHI",PQ_GL_Data!$E:$E,"4010",PQ_GL_Data!$N:$N,"2025-06")-SUMIFS(PQ_GL_Data!$I:$I,PQ_GL_Data!$C:$C,"CHI",PQ_GL_Data!$E:$E,"4010",PQ_GL_Data!$N:$N,"2025-06") -> 29360.01 | E14: =D14-C14 -> -182.59 | F14: =IFERROR(E14/C14,0) -> -0.0061805664 | G14: =RANK(E14,$E$4:$E$35,0) -> 30
A15: CHI | B15: 4020 Corporate & Transactional Fees | C15: =SUMIFS(PQ_Budget_Data!$F:$F,PQ_Budget_Data!$B:$B,"CHI",PQ_Budget_Data!$D:$D,"4020",PQ_Budget_Data!$G:$G,"2025-06") -> 21880.89 | D15: =SUMIFS(PQ_GL_Data!$J:$J,PQ_GL_Data!$C:$C,"CHI",PQ_GL_Data!$E:$E,"4020",PQ_GL_Data!$N:$N,"2025-06")-SUMIFS(PQ_GL_Data!$I:$I,PQ_GL_Data!$C:$C,"CHI",PQ_GL_Data!$E:$E,"4020",PQ_GL_Data!$N:$N,"2025-06") -> 23068.58 | E15: =D15-C15 -> 1187.69 | F15: =IFERROR(E15/C15,0) -> 0.054279785 | G15: =RANK(E15,$E$4:$E$35,0) -> 2
A16: CHI | B16: 4030 Family Law Fees | C16: =SUMIFS(PQ_Budget_Data!$F:$F,PQ_Budget_Data!$B:$B,"CHI",PQ_Budget_Data!$D:$D,"4030",PQ_Budget_Data!$G:$G,"2025-06") -> 16631.01 | D16: =SUMIFS(PQ_GL_Data!$J:$J,PQ_GL_Data!$C:$C,"CHI",PQ_GL_Data!$E:$E,"4030",PQ_GL_Data!$N:$N,"2025-06")-SUMIFS(PQ_GL_Data!$I:$I,PQ_GL_Data!$C:$C,"CHI",PQ_GL_Data!$E:$E,"4030",PQ_GL_Data!$N:$N,"2025-06") -> 17476.19 | E16: =D16-C16 -> 845.18 | F16: =IFERROR(E16/C16,0) -> 0.050819523 | G16: =RANK(E16,$E$4:$E$35,0) -> 4
A17: CHI | B17: 6010 Attorney & Staff Payroll | C17: =SUMIFS(PQ_Budget_Data!$F:$F,PQ_Budget_Data!$B:$B,"CHI",PQ_Budget_Data!$D:$D,"6010",PQ_Budget_Data!$G:$G,"2025-06") -> 30796.33 | D17: =SUMIFS(PQ_GL_Data!$I:$I,PQ_GL_Data!$C:$C,"CHI",PQ_GL_Data!$E:$E,"6010",PQ_GL_Data!$N:$N,"2025-06")-SUMIFS(PQ_GL_Data!$J:$J,PQ_GL_Data!$C:$C,"CHI",PQ_GL_Data!$E:$E,"6010",PQ_GL_Data!$N:$N,"2025-06") -> 30605.68 | E17: =D17-C17 -> -190.65 | F17: =IFERROR(E17/C17,0) -> -0.0061906727 | G17: =RANK(E17,$E$4:$E$35,0) -> 32
A18: CHI | B18: 6020 Payroll Taxes & Benefits | C18: =SUMIFS(PQ_Budget_Data!$F:$F,PQ_Budget_Data!$B:$B,"CHI",PQ_Budget_Data!$D:$D,"6020",PQ_Budget_Data!$G:$G,"2025-06") -> 4365.48 | D18: =SUMIFS(PQ_GL_Data!$I:$I,PQ_GL_Data!$C:$C,"CHI",PQ_GL_Data!$E:$E,"6020",PQ_GL_Data!$N:$N,"2025-06")-SUMIFS(PQ_GL_Data!$J:$J,PQ_GL_Data!$C:$C,"CHI",PQ_GL_Data!$E:$E,"6020",PQ_GL_Data!$N:$N,"2025-06") -> 4284.8 | E18: =D18-C18 -> -80.68 | F18: =IFERROR(E18/C18,0) -> -0.018481358 | G18: =RANK(E18,$E$4:$E$35,0) -> 29
A19: CHI | B19: 6030 Office Rent | C19: =SUMIFS(PQ_Budget_Data!$F:$F,PQ_Budget_Data!$B:$B,"CHI",PQ_Budget_Data!$D:$D,"6030",PQ_Budget_Data!$G:$G,"2025-06") -> 4578.87 | D19: =SUMIFS(PQ_GL_Data!$I:$I,PQ_GL_Data!$C:$C,"CHI",PQ_GL_Data!$E:$E,"6030",PQ_GL_Data!$N:$N,"2025-06")-SUMIFS(PQ_GL_Data!$J:$J,PQ_GL_Data!$C:$C,"CHI",PQ_GL_Data!$E:$E,"6030",PQ_GL_Data!$N:$N,"2025-06") -> 4574.36 | E19: =D19-C19 -> -4.51 | F19: =IFERROR(E19/C19,0) -> -0.00098495917 | G19: =RANK(E19,$E$4:$E$35,0) -> 25
A20: CHI | B20: 6040 Marketing & Business Development | C20: =SUMIFS(PQ_Budget_Data!$F:$F,PQ_Budget_Data!$B:$B,"CHI",PQ_Budget_Data!$D:$D,"6040",PQ_Budget_Data!$G:$G,"2025-06") -> 1888.02 | D20: =SUMIFS(PQ_GL_Data!$I:$I,PQ_GL_Data!$C:$C,"CHI",PQ_GL_Data!$E:$E,"6040",PQ_GL_Data!$N:$N,"2025-06")-SUMIFS(PQ_GL_Data!$J:$J,PQ_GL_Data!$C:$C,"CHI",PQ_GL_Data!$E:$E,"6040",PQ_GL_Data!$N:$N,"2025-06") -> 2019.49 | E20: =D20-C20 -> 131.47 | F20: =IFERROR(E20/C20,0) -> 0.069633796 | G20: =RANK(E20,$E$4:$E$35,0) -> 11
A21: CHI | B21: 6050 Professional Insurance | C21: =SUMIFS(PQ_Budget_Data!$F:$F,PQ_Budget_Data!$B:$B,"CHI",PQ_Budget_Data!$D:$D,"6050",PQ_Budget_Data!$G:$G,"2025-06") -> 884.63 | D21: =SUMIFS(PQ_GL_Data!$I:$I,PQ_GL_Data!$C:$C,"CHI",PQ_GL_Data!$E:$E,"6050",PQ_GL_Data!$N:$N,"2025-06")-SUMIFS(PQ_GL_Data!$J:$J,PQ_GL_Data!$C:$C,"CHI",PQ_GL_Data!$E:$E,"6050",PQ_GL_Data!$N:$N,"2025-06") -> 899 | E21: =D21-C21 -> 14.37 | F21: =IFERROR(E21/C21,0) -> 0.016244079 | G21: =RANK(E21,$E$4:$E$35,0) -> 19
A22: CHI | B22: 6060 Software & IT | C22: =SUMIFS(PQ_Budget_Data!$F:$F,PQ_Budget_Data!$B:$B,"CHI",PQ_Budget_Data!$D:$D,"6060",PQ_Budget_Data!$G:$G,"2025-06") -> 1476.74 | D22: =SUMIFS(PQ_GL_Data!$I:$I,PQ_GL_Data!$C:$C,"CHI",PQ_GL_Data!$E:$E,"6060",PQ_GL_Data!$N:$N,"2025-06")-SUMIFS(PQ_GL_Data!$J:$J,PQ_GL_Data!$C:$C,"CHI",PQ_GL_Data!$E:$E,"6060",PQ_GL_Data!$N:$N,"2025-06") -> 1523.34 | E22: =D22-C22 -> 46.6 | F22: =IFERROR(E22/C22,0) -> 0.031555995 | G22: =RANK(E22,$E$4:$E$35,0) -> 16
A23: CHI | B23: 6070 Shared Services Allocation (Intercompany) | C23: =SUMIFS(PQ_Budget_Data!$F:$F,PQ_Budget_Data!$B:$B,"CHI",PQ_Budget_Data!$D:$D,"6070",PQ_Budget_Data!$G:$G,"2025-06") -> 3772.08 | D23: =SUMIFS(PQ_GL_Data!$I:$I,PQ_GL_Data!$C:$C,"CHI",PQ_GL_Data!$E:$E,"6070",PQ_GL_Data!$N:$N,"2025-06")-SUMIFS(PQ_GL_Data!$J:$J,PQ_GL_Data!$C:$C,"CHI",PQ_GL_Data!$E:$E,"6070",PQ_GL_Data!$N:$N,"2025-06") -> 3772.08 | E23: =D23-C23 -> 0 | F23: =IFERROR(E23/C23,0) -> 0 | G23: =RANK(E23,$E$4:$E$35,0) -> 22
A24: CHI | B24: 7000 Depreciation Expense | C24: =SUMIFS(PQ_Budget_Data!$F:$F,PQ_Budget_Data!$B:$B,"CHI",PQ_Budget_Data!$D:$D,"7000",PQ_Budget_Data!$G:$G,"2025-06") -> 674.57 | D24: =SUMIFS(PQ_GL_Data!$I:$I,PQ_GL_Data!$C:$C,"CHI",PQ_GL_Data!$E:$E,"7000",PQ_GL_Data!$N:$N,"2025-06")-SUMIFS(PQ_GL_Data!$J:$J,PQ_GL_Data!$C:$C,"CHI",PQ_GL_Data!$E:$E,"7000",PQ_GL_Data!$N:$N,"2025-06") -> 682 | E24: =D24-C24 -> 7.43 | F24: =IFERROR(E24/C24,0) -> 0.011014424 | G24: =RANK(E24,$E$4:$E$35,0) -> 20
A25: DAL | B25: 4010 Litigation Fees | C25: =SUMIFS(PQ_Budget_Data!$F:$F,PQ_Budget_Data!$B:$B,"DAL",PQ_Budget_Data!$D:$D,"4010",PQ_Budget_Data!$G:$G,"2025-06") -> 22390.08 | D25: =SUMIFS(PQ_GL_Data!$J:$J,PQ_GL_Data!$C:$C,"DAL",PQ_GL_Data!$E:$E,"4010",PQ_GL_Data!$N:$N,"2025-06")-SUMIFS(PQ_GL_Data!$I:$I,PQ_GL_Data!$C:$C,"DAL",PQ_GL_Data!$E:$E,"4010",PQ_GL_Data!$N:$N,"2025-06") -> 24038.78 | E25: =D25-C25 -> 1648.7 | F25: =IFERROR(E25/C25,0) -> 0.073635288 | G25: =RANK(E25,$E$4:$E$35,0) -> 1
A26: DAL | B26: 4020 Corporate & Transactional Fees | C26: =SUMIFS(PQ_Budget_Data!$F:$F,PQ_Budget_Data!$B:$B,"DAL",PQ_Budget_Data!$D:$D,"4020",PQ_Budget_Data!$G:$G,"2025-06") -> 18574.34 | D26: =SUMIFS(PQ_GL_Data!$J:$J,PQ_GL_Data!$C:$C,"DAL",PQ_GL_Data!$E:$E,"4020",PQ_GL_Data!$N:$N,"2025-06")-SUMIFS(PQ_GL_Data!$I:$I,PQ_GL_Data!$C:$C,"DAL",PQ_GL_Data!$E:$E,"4020",PQ_GL_Data!$N:$N,"2025-06") -> 18887.62 | E26: =D26-C26 -> 313.28 | F26: =IFERROR(E26/C26,0) -> 0.016866279 | G26: =RANK(E26,$E$4:$E$35,0) -> 9
A27: DAL | B27: 4030 Family Law Fees | C27: =SUMIFS(PQ_Budget_Data!$F:$F,PQ_Budget_Data!$B:$B,"DAL",PQ_Budget_Data!$D:$D,"4030",PQ_Budget_Data!$G:$G,"2025-06") -> 13699.69 | D27: =SUMIFS(PQ_GL_Data!$J:$J,PQ_GL_Data!$C:$C,"DAL",PQ_GL_Data!$E:$E,"4030",PQ_GL_Data!$N:$N,"2025-06")-SUMIFS(PQ_GL_Data!$I:$I,PQ_GL_Data!$C:$C,"DAL",PQ_GL_Data!$E:$E,"4030",PQ_GL_Data!$N:$N,"2025-06") -> 14308.8 | E27: =D27-C27 -> 609.11 | F27: =IFERROR(E27/C27,0) -> 0.04446159 | G27: =RANK(E27,$E$4:$E$35,0) -> 8
A28: DAL | B28: 6010 Attorney & Staff Payroll | C28: =SUMIFS(PQ_Budget_Data!$F:$F,PQ_Budget_Data!$B:$B,"DAL",PQ_Budget_Data!$D:$D,"6010",PQ_Budget_Data!$G:$G,"2025-06") -> 27086.88 | D28: =SUMIFS(PQ_GL_Data!$I:$I,PQ_GL_Data!$C:$C,"DAL",PQ_GL_Data!$E:$E,"6010",PQ_GL_Data!$N:$N,"2025-06")-SUMIFS(PQ_GL_Data!$J:$J,PQ_GL_Data!$C:$C,"DAL",PQ_GL_Data!$E:$E,"6010",PQ_GL_Data!$N:$N,"2025-06") -> 27150.2 | E28: =D28-C28 -> 63.32 | F28: =IFERROR(E28/C28,0) -> 0.0023376631 | G28: =RANK(E28,$E$4:$E$35,0) -> 14
A29: DAL | B29: 6020 Payroll Taxes & Benefits | C29: =SUMIFS(PQ_Budget_Data!$F:$F,PQ_Budget_Data!$B:$B,"DAL",PQ_Budget_Data!$D:$D,"6020",PQ_Budget_Data!$G:$G,"2025-06") -> 3819.54 | D29: =SUMIFS(PQ_GL_Data!$I:$I,PQ_GL_Data!$C:$C,"DAL",PQ_GL_Data!$E:$E,"6020",PQ_GL_Data!$N:$N,"2025-06")-SUMIFS(PQ_GL_Data!$J:$J,PQ_GL_Data!$C:$C,"DAL",PQ_GL_Data!$E:$E,"6020",PQ_GL_Data!$N:$N,"2025-06") -> 3801.03 | E29: =D29-C29 -> -18.51 | F29: =IFERROR(E29/C29,0) -> -0.0048461333 | G29: =RANK(E29,$E$4:$E$35,0) -> 26
A30: DAL | B30: 6030 Office Rent | C30: =SUMIFS(PQ_Budget_Data!$F:$F,PQ_Budget_Data!$B:$B,"DAL",PQ_Budget_Data!$D:$D,"6030",PQ_Budget_Data!$G:$G,"2025-06") -> 3997.24 | D30: =SUMIFS(PQ_GL_Data!$I:$I,PQ_GL_Data!$C:$C,"DAL",PQ_GL_Data!$E:$E,"6030",PQ_GL_Data!$N:$N,"2025-06")-SUMIFS(PQ_GL_Data!$J:$J,PQ_GL_Data!$C:$C,"DAL",PQ_GL_Data!$E:$E,"6030",PQ_GL_Data!$N:$N,"2025-06") -> 4057.9 | E30: =D30-C30 -> 60.66 | F30: =IFERROR(E30/C30,0) -> 0.015175471 | G30: =RANK(E30,$E$4:$E$35,0) -> 15
A31: DAL | B31: 6040 Marketing & Business Development | C31: =SUMIFS(PQ_Budget_Data!$F:$F,PQ_Budget_Data!$B:$B,"DAL",PQ_Budget_Data!$D:$D,"6040",PQ_Budget_Data!$G:$G,"2025-06") -> 1836.25 | D31: =SUMIFS(PQ_GL_Data!$I:$I,PQ_GL_Data!$C:$C,"DAL",PQ_GL_Data!$E:$E,"6040",PQ_GL_Data!$N:$N,"2025-06")-SUMIFS(PQ_GL_Data!$J:$J,PQ_GL_Data!$C:$C,"DAL",PQ_GL_Data!$E:$E,"6040",PQ_GL_Data!$N:$N,"2025-06") -> 1653.48 | E31: =D31-C31 -> -182.77 | F31: =IFERROR(E31/C31,0) -> -0.099534377 | G31: =RANK(E31,$E$4:$E$35,0) -> 31
A32: DAL | B32: 6050 Professional Insurance | C32: =SUMIFS(PQ_Budget_Data!$F:$F,PQ_Budget_Data!$B:$B,"DAL",PQ_Budget_Data!$D:$D,"6050",PQ_Budget_Data!$G:$G,"2025-06") -> 797.21 | D32: =SUMIFS(PQ_GL_Data!$I:$I,PQ_GL_Data!$C:$C,"DAL",PQ_GL_Data!$E:$E,"6050",PQ_GL_Data!$N:$N,"2025-06")-SUMIFS(PQ_GL_Data!$J:$J,PQ_GL_Data!$C:$C,"DAL",PQ_GL_Data!$E:$E,"6050",PQ_GL_Data!$N:$N,"2025-06") -> 797.5 | E32: =D32-C32 -> 0.29 | F32: =IFERROR(E32/C32,0) -> 0.00036376864 | G32: =RANK(E32,$E$4:$E$35,0) -> 21
A33: DAL | B33: 6060 Software & IT | C33: =SUMIFS(PQ_Budget_Data!$F:$F,PQ_Budget_Data!$B:$B,"DAL",PQ_Budget_Data!$D:$D,"6060",PQ_Budget_Data!$G:$G,"2025-06") -> 1401.72 | D33: =SUMIFS(PQ_GL_Data!$I:$I,PQ_GL_Data!$C:$C,"DAL",PQ_GL_Data!$E:$E,"6060",PQ_GL_Data!$N:$N,"2025-06")-SUMIFS(PQ_GL_Data!$J:$J,PQ_GL_Data!$C:$C,"DAL",PQ_GL_Data!$E:$E,"6060",PQ_GL_Data!$N:$N,"2025-06") -> 1351.35 | E33: =D33-C33 -> -50.37 | F33: =IFERROR(E33/C33,0) -> -0.035934423 | G33: =RANK(E33,$E$4:$E$35,0) -> 28
A34: DAL | B34: 6070 Shared Services Allocation (Intercompany) | C34: =SUMIFS(PQ_Budget_Data!$F:$F,PQ_Budget_Data!$B:$B,"DAL",PQ_Budget_Data!$D:$D,"6070",PQ_Budget_Data!$G:$G,"2025-06") -> 3346.2 | D34: =SUMIFS(PQ_GL_Data!$I:$I,PQ_GL_Data!$C:$C,"DAL",PQ_GL_Data!$E:$E,"6070",PQ_GL_Data!$N:$N,"2025-06")-SUMIFS(PQ_GL_Data!$J:$J,PQ_GL_Data!$C:$C,"DAL",PQ_GL_Data!$E:$E,"6070",PQ_GL_Data!$N:$N,"2025-06") -> 3346.2 | E34: =D34-C34 -> 0 | F34: =IFERROR(E34/C34,0) -> 0 | G34: =RANK(E34,$E$4:$E$35,0) -> 22
A35: DAL | B35: 7000 Depreciation Expense | C35: =SUMIFS(PQ_Budget_Data!$F:$F,PQ_Budget_Data!$B:$B,"DAL",PQ_Budget_Data!$D:$D,"7000",PQ_Budget_Data!$G:$G,"2025-06") -> 606.79 | D35: =SUMIFS(PQ_GL_Data!$I:$I,PQ_GL_Data!$C:$C,"DAL",PQ_GL_Data!$E:$E,"7000",PQ_GL_Data!$N:$N,"2025-06")-SUMIFS(PQ_GL_Data!$J:$J,PQ_GL_Data!$C:$C,"DAL",PQ_GL_Data!$E:$E,"7000",PQ_GL_Data!$N:$N,"2025-06") -> 605 | E35: =D35-C35 -> -1.79 | F35: =IFERROR(E35/C35,0) -> -0.0029499497 | G35: =RANK(E35,$E$4:$E$35,0) -> 24

Sheet Dashboard_Data
A1: Month | B1: MIA Revenue | C1: CHI Revenue | D1: DAL Revenue | E1: Group Revenue
A2: 2024-01 | B2: =SUMIFS(PQ_GL_Data!$J:$J,PQ_GL_Data!$C:$C,"MIA",PQ_GL_Data!$G:$G,"Revenue",PQ_GL_Data!$H:$H,"No",PQ_GL_Data!$N:$N,"2024-01")-SUMIFS(PQ_GL_Data!$I:$I,PQ_GL_Data!$C:$C,"MIA",PQ_GL_Data!$G:$G,"Revenue",PQ_GL_Data!$H:$H,"No",PQ_GL_Data!$N:$N,"2024-01") -> 95742 | C2: =SUMIFS(PQ_GL_Data!$J:$J,PQ_GL_Data!$C:$C,"CHI",PQ_GL_Data!$G:$G,"Revenue",PQ_GL_Data!$H:$H,"No",PQ_GL_Data!$N:$N,"2024-01")-SUMIFS(PQ_GL_Data!$I:$I,PQ_GL_Data!$C:$C,"CHI",PQ_GL_Data!$G:$G,"Revenue",PQ_GL_Data!$H:$H,"No",PQ_GL_Data!$N:$N,"2024-01") -> 51668.99 | D2: =SUMIFS(PQ_GL_Data!$J:$J,PQ_GL_Data!$C:$C,"DAL",PQ_GL_Data!$G:$G,"Revenue",PQ_GL_Data!$H:$H,"No",PQ_GL_Data!$N:$N,"2024-01")-SUMIFS(PQ_GL_Data!$I:$I,PQ_GL_Data!$C:$C,"DAL",PQ_GL_Data!$G:$G,"Revenue",PQ_GL_Data!$H:$H,"No",PQ_GL_Data!$N:$N,"2024-01") -> 56195.7 | E2: =SUM(B2:D2) -> 203606.69
A3: 2024-02 | B3: =SUMIFS(PQ_GL_Data!$J:$J,PQ_GL_Data!$C:$C,"MIA",PQ_GL_Data!$G:$G,"Revenue",PQ_GL_Data!$H:$H,"No",PQ_GL_Data!$N:$N,"2024-02")-SUMIFS(PQ_GL_Data!$I:$I,PQ_GL_Data!$C:$C,"MIA",PQ_GL_Data!$G:$G,"Revenue",PQ_GL_Data!$H:$H,"No",PQ_GL_Data!$N:$N,"2024-02") -> 100782.2 | C3: =SUMIFS(PQ_GL_Data!$J:$J,PQ_GL_Data!$C:$C,"CHI",PQ_GL_Data!$G:$G,"Revenue",PQ_GL_Data!$H:$H,"No",PQ_GL_Data!$N:$N,"2024-02")-SUMIFS(PQ_GL_Data!$I:$I,PQ_GL_Data!$C:$C,"CHI",PQ_GL_Data!$G:$G,"Revenue",PQ_GL_Data!$H:$H,"No",PQ_GL_Data!$N:$N,"2024-02") -> 60024.83 | D3: =SUMIFS(PQ_GL_Data!$J:$J,PQ_GL_Data!$C:$C,"DAL",PQ_GL_Data!$G:$G,"Revenue",PQ_GL_Data!$H:$H,"No",PQ_GL_Data!$N:$N,"2024-02")-SUMIFS(PQ_GL_Data!$I:$I,PQ_GL_Data!$C:$C,"DAL",PQ_GL_Data!$G:$G,"Revenue",PQ_GL_Data!$H:$H,"No",PQ_GL_Data!$N:$N,"2024-02") -> 57234.04 | E3: =SUM(B3:D3) -> 218041.07
A4: 2024-03 | B4: =SUMIFS(PQ_GL_Data!$J:$J,PQ_GL_Data!$C:$C,"MIA",PQ_GL_Data!$G:$G,"Revenue",PQ_GL_Data!$H:$H,"No",PQ_GL_Data!$N:$N,"2024-03")-SUMIFS(PQ_GL_Data!$I:$I,PQ_GL_Data!$C:$C,"MIA",PQ_GL_Data!$G:$G,"Revenue",PQ_GL_Data!$H:$H,"No",PQ_GL_Data!$N:$N,"2024-03") -> 102950.59 | C4: =SUMIFS(PQ_GL_Data!$J:$J,PQ_GL_Data!$C:$C,"CHI",PQ_GL_Data!$G:$G,"Revenue",PQ_GL_Data!$H:$H,"No",PQ_GL_Data!$N:$N,"2024-03")-SUMIFS(PQ_GL_Data!$I:$I,PQ_GL_Data!$C:$C,"CHI",PQ_GL_Data!$G:$G,"Revenue",PQ_GL_Data!$H:$H,"No",PQ_GL_Data!$N:$N,"2024-03") -> 57700.35 | D4: =SUMIFS(PQ_GL_Data!$J:$J,PQ_GL_Data!$C:$C,"DAL",PQ_GL_Data!$G:$G,"Revenue",PQ_GL_Data!$H:$H,"No",PQ_GL_Data!$N:$N,"2024-03")-SUMIFS(PQ_GL_Data!$I:$I,PQ_GL_Data!$C:$C,"DAL",PQ_GL_Data!$G:$G,"Revenue",PQ_GL_Data!$H:$H,"No",PQ_GL_Data!$N:$N,"2024-03") -> 57987.91 | E4: =SUM(B4:D4) -> 218638.85
A5: 2024-04 | B5: =SUMIFS(PQ_GL_Data!$J:$J,PQ_GL_Data!$C:$C,"MIA",PQ_GL_Data!$G:$G,"Revenue",PQ_GL_Data!$H:$H,"No",PQ_GL_Data!$N:$N,"2024-04")-SUMIFS(PQ_GL_Data!$I:$I,PQ_GL_Data!$C:$C,"MIA",PQ_GL_Data!$G:$G,"Revenue",PQ_GL_Data!$H:$H,"No",PQ_GL_Data!$N:$N,"2024-04") -> 95294.77 | C5: =SUMIFS(PQ_GL_Data!$J:$J,PQ_GL_Data!$C:$C,"CHI",PQ_GL_Data!$G:$G,"Revenue",PQ_GL_Data!$H:$H,"No",PQ_GL_Data!$N:$N,"2024-04")-SUMIFS(PQ_GL_Data!$I:$I,PQ_GL_Data!$C:$C,"CHI",PQ_GL_Data!$G:$G,"Revenue",PQ_GL_Data!$H:$H,"No",PQ_GL_Data!$N:$N,"2024-04") -> 63097.16 | D5: =SUMIFS(PQ_GL_Data!$J:$J,PQ_GL_Data!$C:$C,"DAL",PQ_GL_Data!$G:$G,"Revenue",PQ_GL_Data!$H:$H,"No",PQ_GL_Data!$N:$N,"2024-04")-SUMIFS(PQ_GL_Data!$I:$I,PQ_GL_Data!$C:$C,"DAL",PQ_GL_Data!$G:$G,"Revenue",PQ_GL_Data!$H:$H,"No",PQ_GL_Data!$N:$N,"2024-04") -> 57305.31 | E5: =SUM(B5:D5) -> 215697.24
A6: 2024-05 | B6: =SUMIFS(PQ_GL_Data!$J:$J,PQ_GL_Data!$C:$C,"MIA",PQ_GL_Data!$G:$G,"Revenue",PQ_GL_Data!$H:$H,"No",PQ_GL_Data!$N:$N,"2024-05")-SUMIFS(PQ_GL_Data!$I:$I,PQ_GL_Data!$C:$C,"MIA",PQ_GL_Data!$G:$G,"Revenue",PQ_GL_Data!$H:$H,"No",PQ_GL_Data!$N:$N,"2024-05") -> 95749.8 | C6: =SUMIFS(PQ_GL_Data!$J:$J,PQ_GL_Data!$C:$C,"CHI",PQ_GL_Data!$G:$G,"Revenue",PQ_GL_Data!$H:$H,"No",PQ_GL_Data!$N:$N,"2024-05")-SUMIFS(PQ_GL_Data!$I:$I,PQ_GL_Data!$C:$C,"CHI",PQ_GL_Data!$G:$G,"Revenue",PQ_GL_Data!$H:$H,"No",PQ_GL_Data!$N:$N,"2024-05") -> 58246.34 | D6: =SUMIFS(PQ_GL_Data!$J:$J,PQ_GL_Data!$C:$C,"DAL",PQ_GL_Data!$G:$G,"Revenue",PQ_GL_Data!$H:$H,"No",PQ_GL_Data!$N:$N,"2024-05")-SUMIFS(PQ_GL_Data!$I:$I,PQ_GL_Data!$C:$C,"DAL",PQ_GL_Data!$G:$G,"Revenue",PQ_GL_Data!$H:$H,"No",PQ_GL_Data!$N:$N,"2024-05") -> 50225.28 | E6: =SUM(B6:D6) -> 204221.42
A7: 2024-06 | B7: =SUMIFS(PQ_GL_Data!$J:$J,PQ_GL_Data!$C:$C,"MIA",PQ_GL_Data!$G:$G,"Revenue",PQ_GL_Data!$H:$H,"No",PQ_GL_Data!$N:$N,"2024-06")-SUMIFS(PQ_GL_Data!$I:$I,PQ_GL_Data!$C:$C,"MIA",PQ_GL_Data!$G:$G,"Revenue",PQ_GL_Data!$H:$H,"No",PQ_GL_Data!$N:$N,"2024-06") -> 103409.88 | C7: =SUMIFS(PQ_GL_Data!$J:$J,PQ_GL_Data!$C:$C,"CHI",PQ_GL_Data!$G:$G,"Revenue",PQ_GL_Data!$H:$H,"No",PQ_GL_Data!$N:$N,"2024-06")-SUMIFS(PQ_GL_Data!$I:$I,PQ_GL_Data!$C:$C,"CHI",PQ_GL_Data!$G:$G,"Revenue",PQ_GL_Data!$H:$H,"No",PQ_GL_Data!$N:$N,"2024-06") -> 57739.02 | D7: =SUMIFS(PQ_GL_Data!$J:$J,PQ_GL_Data!$C:$C,"DAL",PQ_GL_Data!$G:$G,"Revenue",PQ_GL_Data!$H:$H,"No",PQ_GL_Data!$N:$N,"2024-06")-SUMIFS(PQ_GL_Data!$I:$I,PQ_GL_Data!$C:$C,"DAL",PQ_GL_Data!$G:$G,"Revenue",PQ_GL_Data!$H:$H,"No",PQ_GL_Data!$N:$N,"2024-06") -> 54002.93 | E7: =SUM(B7:D7) -> 215151.83
A8: 2024-07 | B8: =SUMIFS(PQ_GL_Data!$J:$J,PQ_GL_Data!$C:$C,"MIA",PQ_GL_Data!$G:$G,"Revenue",PQ_GL_Data!$H:$H,"No",PQ_GL_Data!$N:$N,"2024-07")-SUMIFS(PQ_GL_Data!$I:$I,PQ_GL_Data!$C:$C,"MIA",PQ_GL_Data!$G:$G,"Revenue",PQ_GL_Data!$H:$H,"No",PQ_GL_Data!$N:$N,"2024-07") -> 100820.26 | C8: =SUMIFS(PQ_GL_Data!$J:$J,PQ_GL_Data!$C:$C,"CHI",PQ_GL_Data!$G:$G,"Revenue",PQ_GL_Data!$H:$H,"No",PQ_GL_Data!$N:$N,"2024-07")-SUMIFS(PQ_GL_Data!$I:$I,PQ_GL_Data!$C:$C,"CHI",PQ_GL_Data!$G:$G,"Revenue",PQ_GL_Data!$H:$H,"No",PQ_GL_Data!$N:$N,"2024-07") -> 57150.03 | D8: =SUMIFS(PQ_GL_Data!$J:$J,PQ_GL_Data!$C:$C,"DAL",PQ_GL_Data!$G:$G,"Revenue",PQ_GL_Data!$H:$H,"No",PQ_GL_Data!$N:$N,"2024-07")-SUMIFS(PQ_GL_Data!$I:$I,PQ_GL_Data!$C:$C,"DAL",PQ_GL_Data!$G:$G,"Revenue",PQ_GL_Data!$H:$H,"No",PQ_GL_Data!$N:$N,"2024-07") -> 53821.7 | E8: =SUM(B8:D8) -> 211791.99
A9: 2024-08 | B9: =SUMIFS(PQ_GL_Data!$J:$J,PQ_GL_Data!$C:$C,"MIA",PQ_GL_Data!$G:$G,"Revenue",PQ_GL_Data!$H:$H,"No",PQ_GL_Data!$N:$N,"2024-08")-SUMIFS(PQ_GL_Data!$I:$I,PQ_GL_Data!$C:$C,"MIA",PQ_GL_Data!$G:$G,"Revenue",PQ_GL_Data!$H:$H,"No",PQ_GL_Data!$N:$N,"2024-08") -> 91346.81 | C9: =SUMIFS(PQ_GL_Data!$J:$J,PQ_GL_Data!$C:$C,"CHI",PQ_GL_Data!$G:$G,"Revenue",PQ_GL_Data!$H:$H,"No",PQ_GL_Data!$N:$N,"2024-08")-SUMIFS(PQ_GL_Data!$I:$I,PQ_GL_Data!$C:$C,"CHI",PQ_GL_Data!$G:$G,"Revenue",PQ_GL_Data!$H:$H,"No",PQ_GL_Data!$N:$N,"2024-08") -> 66989.57 | D9: =SUMIFS(PQ_GL_Data!$J:$J,PQ_GL_Data!$C:$C,"DAL",PQ_GL_Data!$G:$G,"Revenue",PQ_GL_Data!$H:$H,"No",PQ_GL_Data!$N:$N,"2024-08")-SUMIFS(PQ_GL_Data!$I:$I,PQ_GL_Data!$C:$C,"DAL",PQ_GL_Data!$G:$G,"Revenue",PQ_GL_Data!$H:$H,"No",PQ_GL_Data!$N:$N,"2024-08") -> 50656.97 | E9: =SUM(B9:D9) -> 208993.35
A10: 2024-09 | B10: =SUMIFS(PQ_GL_Data!$J:$J,PQ_GL_Data!$C:$C,"MIA",PQ_GL_Data!$G:$G,"Revenue",PQ_GL_Data!$H:$H,"No",PQ_GL_Data!$N:$N,"2024-09")-SUMIFS(PQ_GL_Data!$I:$I,PQ_GL_Data!$C:$C,"MIA",PQ_GL_Data!$G:$G,"Revenue",PQ_GL_Data!$H:$H,"No",PQ_GL_Data!$N:$N,"2024-09") -> 100145 | C10: =SUMIFS(PQ_GL_Data!$J:$J,PQ_GL_Data!$C:$C,"CHI",PQ_GL_Data!$G:$G,"Revenue",PQ_GL_Data!$H:$H,"No",PQ_GL_Data!$N:$N,"2024-09")-SUMIFS(PQ_GL_Data!$I:$I,PQ_GL_Data!$C:$C,"CHI",PQ_GL_Data!$G:$G,"Revenue",PQ_GL_Data!$H:$H,"No",PQ_GL_Data!$N:$N,"2024-09") -> 68696.42 | D10: =SUMIFS(PQ_GL_Data!$J:$J,PQ_GL_Data!$C:$C,"DAL",PQ_GL_Data!$G:$G,"Revenue",PQ_GL_Data!$H:$H,"No",PQ_GL_Data!$N:$N,"2024-09")-SUMIFS(PQ_GL_Data!$I:$I,PQ_GL_Data!$C:$C,"DAL",PQ_GL_Data!$G:$G,"Revenue",PQ_GL_Data!$H:$H,"No",PQ_GL_Data!$N:$N,"2024-09") -> 52956.27 | E10: =SUM(B10:D10) -> 221797.69
